Workbook

Sheet 1-Mar
A1: Production Output
A2: Filter: Date Completed: 01/03/25
A4: Work Order No. | B4: Work Order Line No. | C4: WO Journal Line No. | D4: Add Date | E4: Add User | F4: Add Time | G4: Material Batch No. | H4: Die Cut | I4: Process No. | J4: Posted | K4: Machine Code | L4: Staff Code | M4: No. of Press | N4: Date Started | O4: Time Started | P4: Date Completed | Q4: Time Completed | R4: No. of Ups | S4: Printed Quantity | T4: Journal Type | U4: Item Code | V4: Quantity | W4: QC Approved Quantity | X4: Rejected Quantity | Y4: Roll | Z4: Length | AA4: Width | AB4: Length UOM | AC4: Width UOM | AD4: RM Quantity | AE4: Material Code | AF4: Variant Code | AG4: Request Delivery Date | AH4: Non QC Record | AI4: Link to Line No. | AJ4: Related | AK4: Expire Date | AL4: Label Remark | AM4: Customer Part Number | AN4: Customer Code | AO4: ddmm | AP4: Label Packing Quantity 1 | AQ4: Label Quantity 1 | AR4: Label Packing Quantity 2 | AS4: Label Quantity 2 | AT4: Label Packing Quantity 3 | AU4: Label Quantity 3 | AV4: UOM for Label Printing | AW4: QC Inspector | AX4: Summarised Period | AY4: Summarised | AZ4: Posted Work Order No. | BA4: Colour | BB4: Currency | BC4: Ref Customer | BD4: Group | BE4: PO | BF4: Source Doc. No.
A5: W0672678 | B5: 10000 | C5: 40000 | D5: 45720 | E5: 502LAUGH | F5: 0.46662037 | G5: 10639931017/10639931014 | I5: 2 | J5: Yes | K5: 86 | L5: PM45 | M5: 8334 | P5: 45717 | R5: 36 | S5: 300024 | T5: PE | U5: 5180-0100-BH2120001 | V5: 0 | W5: 280379 | X5: 19645 | Y5: 0 | Z5: 0 | AA5: 0 | AD5: 0 | AM5: 5180-0100-BH212 | AN5: H08031-JIM | AP5: 0 | AQ5: 0 | AR5: 0 | AS5: 0 | AT5: 0 | AU5: 0 | AY5: No | AZ5: W662404 | BA5: 0 | BC5: H08031-JIM | BF5: S0350610
A6: W0675375 | B6: 10000 | C6: 30000 | D6: 45719 | E6: 502LAUGH | F6: 4:49:47 pm | G6: 10584752088/10584752089/10584752090/10584752091/10584752092 | I6: 3 | J6: Yes | K6: 91 | L6: QM87 | M6: 56000 | P6: 45717 | R6: 9 | S6: 504000 | T6: PE | U6: 5180-0103-BH2120001 | V6: 0 | W6: 500000 | X6: 4000 | Y6: 0 | Z6: 0 | AA6: 0 | AD6: 0 | AM6: 5180-0103-BH212 | AN6: H08031-JIM | AP6: 0 | AQ6: 0 | AR6: 0 | AS6: 0 | AT6: 0 | AU6: 0 | AY6: No | AZ6: W662929 | BA6: 0 | BC6: H08031-JIM | BF6: S0353172
A7: W0675403 | B7: 10000 | C7: 30000 | D7: 45730 | E7: 502LAUGH | F7: 8:37:26 am | G7: 10639931087/10639931085/10620258096/10620258095/10620258094 | I7: 2 | J7: Yes | K7: 86 | L7: PM45 | M7: 29723 | P7: 45717 | R7: 36 | S7: 1070028 | T7: PE | U7: 5180-0102-BH2120001 | V7: 0 | W7: 1000000 | X7: 70028 | Y7: 0 | Z7: 0 | AA7: 0 | AD7: 0 | AM7: 5180-0102-BH212 | AN7: H08031-JIM | AP7: 0 | AQ7: 0 | AR7: 0 | AS7: 0 | AT7: 0 | AU7: 0 | AY7: No | AZ7: W662931 | BA7: 0 | BC7: H08031-JIM | BF7: S0353204
A8: W0678396 | B8: 10000 | C8: 20000 | D8: 45719 | E8: 502LAUGH | F8: 9:00:27 am | G8: SG-564141001 | I8: 1 | J8: Yes | K8: 73 | L8: PM59 | M8: 24000 | P8: 45717 | R8: 12 | S8: 288000 | T8: PE | U8: 80256220001 | V8: 0 | W8: 288000 | X8: 0 | Y8: 0 | Z8: 0 | AA8: 0 | AD8: 0 | AM8: 8025622 | AN8: B02083 | AP8: 0 | AQ8: 0 | AR8: 0 | AS8: 0 | AT8: 0 | AU8: 0 | AY8: No | AZ8: W662946 | BA8: 0 | BC8: B02083 | BF8: S0357120
A9: W0678397 | B9: 10000 | C9: 10000 | D9: 45719 | E9: 505KANGHS | F9: 8:39:41 am | G9: SG-564141001 | I9: 1 | J9: Yes | K9: 73N | L9: PM18 | M9: 36000 | P9: 45717 | R9: 12 | S9: 432000 | T9: PE | U9: 80256220001 | V9: 0 | W9: 432000 | X9: 0 | Y9: 0 | Z9: 0 | AA9: 0 | AD9: 0 | AM9: 8025622 | AN9: B02083 | AP9: 0 | AQ9: 0 | AR9: 0 | AS9: 0 | AT9: 0 | AU9: 0 | AY9: No | AZ9: W663294 | BA9: 0 | BC9: B02083 | BF9: S0357121
A10: W0678636 | B10: 10000 | C10: 30000 | D10: 45719 | E10: 502LAUGH | F10: 8:54:11 am | G10: D007Y0190/D006A5780/D007Y0190 | I10: 3 | J10: Yes | K10: 101 | L10: QM54 | M10: 34000 | P10: 45717 | R10: 3 | S10: 102000 | T10: PE | U10: 1VU26-80043-FT0001 | V10: 0 | W10: 110000 | X10: -8000 | Y10: 0 | Z10: 0 | AA10: 0 | AD10: 0 | AM10: 1VU26-80043-FT | AN10: H08031-JIM-M | AP10: 0 | AQ10: 0 | AR10: 0 | AS10: 0 | AT10: 0 | AU10: 0 | AY10: No | AZ10: W661939 | BA10: 0 | BC10: H08031-JIM-M | BF10: S0357400
A11: W0679261 | B11: 10000 | C11: 10000 | D11: 45719 | E11: 502LAUGH | F11: 8:40:28 am | G11: 4103018U5A | I11: 1 | J11: Yes | K11: 46 | L11: PS66 | M11: 4000 | P11: 45717 | R11: 1 | S11: 4000 | T11: PE | U11: 260-6403-000001 | V11: 0 | W11: 4000 | X11: 0 | Y11: 0 | Z11: 0 | AA11: 0 | AD11: 0 | AM11: 260-6403-00 | AN11: J10025 | AP11: 0 | AQ11: 0 | AR11: 0 | AS11: 0 | AT11: 0 | AU11: 0 | AY11: No | AZ11: W662152 | BA11: 0 | BC11: J10025 | BF11: S0357888
A12: W0679265 | B12: 10000 | C12: 30000 | D12: 45721 | E12: 502LAUGH | F12: 2:58:25 pm | G12: 4103018U5A | I12: 1 | J12: Yes | K12: 46 | L12: PS66 | M12: 2000 | P12: 45717 | R12: 1 | S12: 2000 | T12: PE | U12: 260-6482-000001 | V12: 0 | W12: 2000 | X12: 0 | Y12: 0 | Z12: 0 | AA12: 0 | AD12: 0 | AM12: 260-6482-00 | AN12: J10025 | AP12: 0 | AQ12: 0 | AR12: 0 | AS12: 0 | AT12: 0 | AU12: 0 | AY12: No | AZ12: W662205 | BA12: 0 | BC12: J10025 | BF12: S0357888
A13: W0679360 | B13: 10000 | C13: 20000 | D13: 45720 | E13: 502LAUGH | F13: 8:37:07 am | G13: D005I8320/D00676710 | I13: 2 | J13: Yes | K13: 77 | L13: PM74 | M13: 10600 | P13: 45717 | R13: 10 | S13: 106000 | T13: PE | U13: 6ZE06-80002-FT0001 | V13: 0 | W13: 100000 | X13: 6000 | Y13: 0 | Z13: 0 | AA13: 0 | AD13: 0 | AM13: 6ZE06-80002-FT | AN13: H08031-JIM-M | AP13: 0 | AQ13: 0 | AR13: 0 | AS13: 0 | AT13: 0 | AU13: 0 | AY13: No | AZ13: W662154 | BA13: 0 | BC13: H08031-JIM-M | BF13: S0358096
A14: W0679476 | B14: 10000 | C14: 20000 | D14: 45719 | E14: 502LAUGH | F14: 8:45:36 am | G14: J00T59660 | I14: 2 | J14: Yes | K14: 71 | L14: PS95 | M14: 4167 | P14: 45717 | R14: 6 | S14: 25002 | T14: PE | U14: 86090880001 | V14: 0 | W14: 25000 | X14: 2 | Y14: 0 | Z14: 0 | AA14: 0 | AD14: 0 | AM14: 8609088 | AN14: B02083 | AP14: 0 | AQ14: 0 | AR14: 0 | AS14: 0 | AT14: 0 | AU14: 0 | AY14: No | AZ14: W661986 | BA14: 0 | BC14: B02083 | BF14: S0358239
A15: W0679477 | B15: 10000 | C15: 20000 | D15: 45719 | E15: 502LAUGH | F15: 8:47:06 am | G15: J00T59660 | I15: 2 | J15: Yes | K15: 71 | L15: PS95 | M15: 1667 | P15: 45717 | R15: 6 | S15: 10002 | T15: PE | U15: 86090890001 | V15: 0 | W15: 10000 | X15: 2 | Y15: 0 | Z15: 0 | AA15: 0 | AD15: 0 | AM15: 8609089 | AN15: B02083 | AP15: 0 | AQ15: 0 | AR15: 0 | AS15: 0 | AT15: 0 | AU15: 0 | AY15: No | AZ15: W661987 | BA15: 0 | BC15: B02083 | BF15: S0358239
A16: W0679478 | B16: 10000 | C16: 20000 | D16: 45719 | E16: 502LAUGH | F16: 8:46:22 am | G16: J00T59660 | I16: 2 | J16: Yes | K16: 71 | L16: PS95 | M16: 1667 | P16: 45717 | R16: 6 | S16: 10002 | T16: PE | U16: 86090900001 | V16: 0 | W16: 10000 | X16: 2 | Y16: 0 | Z16: 0 | AA16: 0 | AD16: 0 | AM16: 8609090 | AN16: B02083 | AP16: 0 | AQ16: 0 | AR16: 0 | AS16: 0 | AT16: 0 | AU16: 0 | AY16: No | AZ16: W661988 | BA16: 0 | BC16: B02083 | BF16: S0358239
A17: W0679521 | B17: 10000 | C17: 20000 | D17: 45719 | E17: 502LAUGH | F17: 3:36:54 pm | G17: D00676710/D005I8320 | I17: 2 | J17: Yes | K17: 77 | L17: PM74 | M17: 18500 | P17: 45717 | R17: 10 | S17: 185000 | T17: PE | U17: 6ZE04-80002-FT0001 | V17: 0 | W17: 175000 | X17: 10000 | Y17: 0 | Z17: 0 | AA17: 0 | AD17: 0 | AM17: 6ZE04-80002-FT | AN17: H08031-JIM-M | AP17: 0 | AQ17: 0 | AR17: 0 | AS17: 0 | AT17: 0 | AU17: 0 | AY17: No | AZ17: W662155 | BA17: 0 | BC17: H08031-JIM-M | BF17: S0358297
A18: W0679579 | B18: 10000 | C18: 10000 | D18: 45719 | E18: 502LAUGH | F18: 9:12:20 am | G18: 5305412-04-02-06/5305412-04-03-01/5305412-04-03-03 | I18: 1 | J18: Yes | K18: 90 | L18: QC04 | M18: 27000 | P18: 45717 | R18: 2 | S18: 54000 | T18: PE | U18: 723852900-PROTO 0001 | V18: 0 | W18: 54000 | X18: 0 | Y18: 0 | Z18: 0 | AA18: 0 | AD18: 0 | AM18: 723852900-PROTO D | AN18: S19314 | AP18: 0 | AQ18: 0 | AR18: 0 | AS18: 0 | AT18: 0 | AU18: 0 | AY18: No | AZ18: W662206 | BA18: 0 | BC18: S19314 | BF18: H0064583
A19: W0679612 | B19: 10000 | C19: 30000 | D19: 45719 | E19: 502LAUGH | F19: 8:50:40 am | G19: 40085H051 | I19: 2 | J19: Yes | K19: 60 | L19: PM17 | M19: 5000 | P19: 45717 | R19: 1 | S19: 5000 | T19: PE | U19: FRAGILE LABEL0004 | V19: 0 | W19: 3378 | X19: 1622 | Y19: 0 | Z19: 0 | AA19: 0 | AD19: 0 | AM19: FRAGILE LABEL | AN19: M13367 | AP19: 0 | AQ19: 0 | AR19: 0 | AS19: 0 | AT19: 0 | AU19: 0 | AY19: No | AZ19: W662011 | BA19: 0 | BC19: M13367 | BF19: S0358328
A20: W0679666 | B20: 10000 | C20: 10000 | D20: 45720 | E20: 502LAUGH | F20: 4:03:05 pm | G20: E0801904/M0BSO4480 | I20: 1 | J20: Yes | K20: 87 | L20: PM14 | M20: 20250 | P20: 45717 | R20: 2 | S20: 40500 | T20: PE | U20: 762070100 REVA0001 | V20: 0 | W20: 40500 | X20: 0 | Y20: 0 | Z20: 0 | AA20: 0 | AD20: 0 | AM20: 762070100 REVA | AN20: S19081-TH | AP20: 0 | AQ20: 0 | AR20: 0 | AS20: 0 | AT20: 0 | AU20: 0 | AY20: No | AZ20: W662136 | BA20: 0 | BC20: S19081-TH | BF20: H0064623
A21: W0679688 | B21: 10000 | C21: 10000 | D21: 45719 | E21: 502LAUGH | F21: 8:57:51 am | G21: SG-5630465 | I21: 1 | J21: Yes | K21: 59 | L21: PM09 | M21: 258 | P21: 45717 | R21: 4 | S21: 1032 | T21: PE | U21: 112887750001 | V21: 0 | W21: 1030 | X21: 2 | Y21: 0 | Z21: 0 | AA21: 0 | AD21: 0 | AM21: 11288775 | AN21: I09180 | AP21: 0 | AQ21: 0 | AR21: 0 | AS21: 0 | AT21: 0 | AU21: 0 | AY21: No | AZ21: W662016 | BA21: 0 | BC21: I09180 | BF21: S0358363
A22: W0679753 | B22: 10000 | C22: 10000 | D22: 45719 | E22: 502LAUGH | F22: 8:59:11 am | G22: G2329005 | I22: 1 | J22: Yes | K22: 78 | L22: PM84 | M22: 1667 | P22: 45717 | R22: 3 | S22: 5001 | T22: PE | U22: 0098-85000001 | V22: 0 | W22: 5000 | X22: 1 | Y22: 0 | Z22: 0 | AA22: 0 | AD22: 0 | AM22: C02-0098-8500 | AN22: G07042-M | AP22: 0 | AQ22: 0 | AR22: 0 | AS22: 0 | AT22: 0 | AU22: 0 | AY22: No | AZ22: W662023 | BA22: 0 | BC22: G07042-M | BF22: S0358422
A23: W0679913 | B23: 10000 | C23: 10000 | D23: 45719 | E23: 502LAUGH | F23: 5:19:21 pm | G23: 4111523U5A/4111522U5A/4111521U5A | I23: 1 | J23: Yes | K23: 61 | L23: PM61 | M23: 8334 | P23: 45717 | R23: 6 | S23: 50004 | T23: PE | U23: 260-6012-000001 | V23: 0 | W23: 50000 | X23: 4 | Y23: 0 | Z23: 0 | AA23: 0 | AD23: 0 | AM23: 260-6012-00 | AN23: J10025 | AP23: 0 | AQ23: 0 | AR23: 0 | AS23: 0 | AT23: 0 | AU23: 0 | AY23: No | AZ23: W662213 | BA23: 0 | BC23: J10025 | BF23: S0358486
A24: W0680071 | B24: 10000 | C24: 10000 | D24: 45719 | E24: 502LAUGH | F24: 8:59:11 am | G24: 4071802U5 | I24: 1 | J24: Yes | K24: 78 | L24: PM84 | M24: 6000 | P24: 45717 | R24: 1 | S24: 6000 | T24: PE | U24: 807192 REV 4000001 | V24: 0 | W24: 6000 | X24: 0 | Y24: 0 | Z24: 0 | AA24: 0 | AD24: 0 | AM24: 807192 REV 400 | AN24: V22000 | AP24: 0 | AQ24: 0 | AR24: 0 | AS24: 0 | AT24: 0 | AU24: 0 | AY24: No | AZ24: W662037 | BA24: 0 | BC24: V22000 | BF24: S0358750
A25: W0680094 | B25: 10000 | C25: 20000 | D25: 45719 | E25: 502LAUGH | F25: 8:44:51 am | G25: J00T59660 | I25: 2 | J25: Yes | K25: 71 | L25: PS95 | M25: 1667 | P25: 45717 | R25: 6 | S25: 10002 | T25: PE | U25: 80834720001 | V25: 0 | W25: 10000 | X25: 2 | Y25: 0 | Z25: 0 | AA25: 0 | AD25: 0 | AM25: 8083472 | AN25: B02083 | AP25: 0 | AQ25: 0 | AR25: 0 | AS25: 0 | AT25: 0 | AU25: 0 | AY25: No | AZ25: W662040 | BA25: 0 | BC25: B02083 | BF25: S0358764
A26: W0680240 | B26: 10000 | C26: 10000 | D26: 45719 | E26: 502LAUGH | F26: 8:36:45 am | G26: U3B12S049 | I26: 61 | J26: Yes | K26: 61 | L26: PM68 | M26: 1250 | P26: 45717 | R26: 8 | S26: 10000 | T26: PE | U26: 039714 REV5000001 | V26: 0 | W26: 10000 | X26: 0 | Y26: 0 | Z26: 0 | AA26: 0 | AD26: 0 | AM26: 039714 REV500 | AN26: V22000 | AP26: 0 | AQ26: 0 | AR26: 0 | AS26: 0 | AT26: 0 | AU26: 0 | AY26: No | AZ26: W662051 | BA26: 0 | BC26: V22000 | BF26: S0359014
A27: W0680267 | B27: 10000 | C27: 10000 | D27: 45719 | E27: 502LAUGH | F27: 8:56:30 am | G27: SG-5630465 | I27: 1 | J27: Yes | K27: 59 | L27: PM09 | M27: 2130 | P27: 45717 | R27: 2 | S27: 4260 | T27: PE | U27: 150281190001 | V27: 0 | W27: 4260 | X27: 0 | Y27: 0 | Z27: 0 | AA27: 0 | AD27: 0 | AM27: 15028119 | AN27: I09180 | AP27: 0 | AQ27: 0 | AR27: 0 | AS27: 0 | AT27: 0 | AU27: 0 | AY27: No | AZ27: W662053 | BA27: 0 | BC27: I09180 | BF27: S0359039
A28: W0680274 | B28: 10000 | C28: 30000 | D28: 45720 | E28: 502LAUGH | F28: 8:34:26 am | G28: SG-5641511-01 | I28: 3 | J28: Yes | K28: 73 | L28: PS96 | M28: 207000 | P28: 45717 | R28: 1 | S28: 207000 | T28: PE | U28: 150370360001 | V28: 0 | W28: 122826 | X28: 84174 | Y28: 0 | Z28: 0 | AA28: 0 | AD28: 0 | AM28: 15037036 | AN28: I09180 | AP28: 0 | AQ28: 0 | AR28: 0 | AS28: 0 | AT28: 0 | AU28: 0 | AY28: No | AZ28: W662218 | BA28: 0 | BC28: I09180 | BF28: S0359046
A29: W0680344 | B29: 10000 | C29: 20000 | D29: 45719 | E29: 502LAUGH | F29: 8:49:12 am | G29: J00T59660 | I29: 2 | J29: Yes | K29: 71 | L29: PS95 | M29: 834 | P29: 45717 | R29: 6 | S29: 5004 | T29: PE | U29: 5000582250001 | V29: 0 | W29: 5000 | X29: 4 | Y29: 0 | Z29: 0 | AA29: 0 | AD29: 0 | AM29: 500058225 | AN29: B02083 | AP29: 0 | AQ29: 0 | AR29: 0 | AS29: 0 | AT29: 0 | AU29: 0 | AY29: No | AZ29: W662063 | BA29: 0 | BC29: B02083 | BF29: S0359167
A30: W0680345 | B30: 10000 | C30: 20000 | D30: 45719 | E30: 502LAUGH | F30: 8:48:34 am | G30: J00T59660 | I30: 2 | J30: Yes | K30: 71 | L30: PS95 | M30: 834 | P30: 45717 | R30: 6 | S30: 5004 | T30: PE | U30: 5000596240001 | V30: 0 | W30: 5000 | X30: 4 | Y30: 0 | Z30: 0 | AA30: 0 | AD30: 0 | AM30: 500059624 | AN30: B02083 | AP30: 0 | AQ30: 0 | AR30: 0 | AS30: 0 | AT30: 0 | AU30: 0 | AY30: No | AZ30: W662064 | BA30: 0 | BC30: B02083 | BF30: S0359167
A31: W0680450 | B31: 10000 | C31: 20000 | D31: 45719 | E31: 505KANGHS | F31: 8:33:33 am | G31: SG-5642459-01 | I31: 2 | J31: Yes | K31: 86 | L31: PM45 | M31: 1400 | P31: 45717 | R31: 1 | S31: 1400 | T31: PE | U31: P4U01160001 | V31: 0 | W31: 1000 | X31: 400 | Y31: 0 | Z31: 0 | AA31: 0 | AD31: 0 | AM31: P4U0116 | AN31: H08220 | AP31: 0 | AQ31: 0 | AR31: 0 | AS31: 0 | AT31: 0 | AU31: 0 | AY31: No | AZ31: W662177 | BA31: 0 | BC31: H08220 | BF31: S0359243
A32: W0680593 | B32: 10000 | C32: 10000 | D32: 45719 | E32: 502LAUGH | F32: 5:36:36 pm | G32: M0BTH2381 | I32: 1 | J32: Yes | K32: 29 | L32: PS70 | M32: 24000 | P32: 45717 | R32: 2 | S32: 48000 | T32: PE | U32: 100823881-75367 0001 | V32: 0 | W32: 48000 | X32: 0 | Y32: 0 | Z32: 0 | AA32: 0 | AD32: 0 | AM32: 100823881-75367 A | AN32: S19081-TH | AP32: 0 | AQ32: 0 | AR32: 0 | AS32: 0 | AT32: 0 | AU32: 0 | AY32: No | AZ32: W663026 | BA32: 0 | BC32: S19081-TH | BF32: H0064686
A33: W0680743 | B33: 10000 | C33: 10000 | D33: 45719 | E33: 502LAUGH | F33: 8:56:30 am | G33: SG-5630465 | I33: 1 | J33: Yes | K33: 59 | L33: PM09 | M33: 258 | P33: 45717 | R33: 4 | S33: 1032 | T33: PE | U33: 112887410001 | V33: 0 | W33: 1030 | X33: 2 | Y33: 0 | Z33: 0 | AA33: 0 | AD33: 0 | AM33: 11288741 | AN33: I09180 | AP33: 0 | AQ33: 0 | AR33: 0 | AS33: 0 | AT33: 0 | AU33: 0 | AY33: No | AZ33: W662078 | BA33: 0 | BC33: I09180 | BF33: S0359857
A36: =COUNTA(A5:A33) -> 29

Sheet 3_Mar
A1: Production Output
A2: Filter: Date Completed: 03/03/25
A4: Work Order No. | B4: Work Order Line No. | C4: WO Journal Line No. | D4: Add Date | E4: Add User | F4: Add Time | G4: Material Batch No. | H4: Die Cut | I4: Process No. | J4: Posted | K4: Machine Code | L4: Staff Code | M4: No. of Press | N4: Date Started | O4: Time Started | P4: Date Completed | Q4: Time Completed | R4: No. of Ups | S4: Printed Quantity | T4: Journal Type | U4: Item Code | V4: Quantity | W4: QC Approved Quantity | X4: Rejected Quantity | Y4: Roll | Z4: Length | AA4: Width | AB4: Length UOM | AC4: Width UOM | AD4: RM Quantity | AE4: Material Code | AF4: Variant Code | AG4: Request Delivery Date | AH4: Non QC Record | AI4: Link to Line No. | AJ4: Related | AK4: Expire Date | AL4: Label Remark | AM4: Customer Part Number | AN4: Customer Code | AO4: ddmm | AP4: Label Packing Quantity 1 | AQ4: Label Quantity 1 | AR4: Label Packing Quantity 2 | AS4: Label Quantity 2 | AT4: Label Packing Quantity 3 | AU4: Label Quantity 3 | AV4: UOM for Label Printing | AW4: QC Inspector | AX4: Summarised Period | AY4: Summarised | AZ4: Posted Work Order No. | BA4: Colour | BB4: Currency | BC4: Ref Customer | BD4: Group | BE4: PO | BF4: Source Doc. No.
A5: W0667474 | B5: 10000 | C5: 10000 | D5: 45719 | E5: 502LAUGH | F5: 5:20:26 pm | G5: E04H968101524 | I5: 1 | J5: Yes | K5: 86 | L5: PM45 | M5: 632 | P5: 45719 | R5: 8 | S5: 5056 | T5: PE | U5: 10051353053 REVF0001 | V5: 0 | W5: 5050 | X5: 6 | Y5: 0 | Z5: 0 | AA5: 0 | AD5: 0 | AM5: 10051353053 REVF | AN5: E05166 | AP5: 0 | AQ5: 0 | AR5: 0 | AS5: 0 | AT5: 0 | AU5: 0 | AY5: No | AZ5: W661922 | BA5: 0 | BC5: E05166 | BF5: S0345943
A6: W0672678 | B6: 10000 | C6: 60000 | D6: 45720 | E6: 502LAUGH | F6: 0.46662037 | G6: 10639931017/10639931014 | I6: 3 | J6: Yes | K6: 91 | L6: QM87 | M6: 36000 | P6: 45719 | R6: 9 | S6: 324000 | T6: PE | U6: 5180-0100-BH2120001 | V6: 0 | W6: 321429 | X6: 2571 | Y6: 0 | Z6: 0 | AA6: 0 | AD6: 0 | AM6: 5180-0100-BH212 | AN6: H08031-JIM | AP6: 0 | AQ6: 0 | AR6: 0 | AS6: 0 | AT6: 0 | AU6: 0 | AY6: No | AZ6: W662404 | BA6: 0 | BC6: H08031-JIM | BF6: S0350610
A7: W0673664 | B7: 10000 | C7: 10000 | D7: 45719 | E7: 505KANGHS | F7: 8:39:41 am | G7: D00636982 | I7: 1 | J7: Yes | K7: 65 | L7: PMJ7 | M7: 18000 | P7: 45719 | R7: 12 | S7: 216000 | T7: PE | U7: R630-401 REV2.00001 | V7: 0 | W7: 216000 | X7: 0 | Y7: 0 | Z7: 0 | AA7: 0 | AD7: 0 | AM7: R630-401 REV2.0 | AN7: R18131 | AP7: 0 | AQ7: 0 | AR7: 0 | AS7: 0 | AT7: 0 | AU7: 0 | AY7: No | AZ7: W662196 | BA7: 0 | BC7: R18131 | BF7: S0351464
A8: W0674490 | B8: 10000 | C8: 20000 | D8: 45720 | E8: 502LAUGH | F8: 3:06:08 pm | G8: PO2512640 | I8: 1 | J8: Yes | K8: 60 | L8: PM30 | M8: 6000 | P8: 45719 | R8: 1 | S8: 6000 | T8: PE | U8: G11-4600-040001 | V8: 0 | W8: 6000 | X8: 0 | Y8: 0 | Z8: 0 | AA8: 0 | AD8: 0 | AM8: G11-4600-04 | AN8: Z26005 | AP8: 0 | AQ8: 0 | AR8: 0 | AS8: 0 | AT8: 0 | AU8: 0 | AY8: No | AZ8: W662138 | BA8: 0 | BC8: Z26005 | BF8: S0352625
A9: W0674926 | B9: 10000 | C9: 20000 | D9: 45719 | E9: 502LAUGH | F9: 5:16:19 pm | G9: J00T40250/J00U09620 | I9: 1 | J9: Yes | K9: 111 | L9: PM46 | M9: 15000 | P9: 45719 | R9: 10 | S9: 150000 | T9: PE | U9: Z512-M0001 | V9: 0 | W9: 150000 | X9: 0 | Y9: 0 | Z9: 0 | AA9: 0 | AD9: 0 | AM9: Z512-M | AN9: R18131-MEIBAN MICRO | AP9: 0 | AQ9: 0 | AR9: 0 | AS9: 0 | AT9: 0 | AU9: 0 | AY9: No | AZ9: W662407 | BA9: 0 | BC9: R18131-MEIBAN MICRO | BF9: S0352982
A10: W0675399 | B10: 10000 | C10: 20000 | D10: 45749 | E10: 502LAUGH | F10: 2:18:31 pm | G10: 10639931053/10639931059/10639931056/10639931055 | I10: 1 | J10: Yes | K10: 79N | L10: PM21 | M10: 10093 | P10: 45719 | R10: 108 | S10: 1090044 | T10: PE | U10: 5180-0100-BH2120001 | V10: 0 | W10: 1000000 | X10: 90044 | Y10: 0 | Z10: 0 | AA10: 0 | AD10: 0 | AM10: 5180-0100-BH212 | AN10: H08031-JIM | AP10: 0 | AQ10: 0 | AR10: 0 | AS10: 0 | AT10: 0 | AU10: 0 | AY10: No | AZ10: W664068 | BA10: 0 | BC10: H08031-JIM | BF10: S0353202
A11: W0676465 | B11: 10000 | C11: 10000 | D11: 45723 | E11: 502LAUGH | F11: 0.47342593 | G11: J00T59660/J00V80140/J00U09620/J00T40250 | I11: 1 | J11: Yes | K11: 111 | L11: PM46 | M11: 60000 | P11: 45719 | R11: 10 | S11: 600000 | T11: PE | U11: Z512-M0001 | V11: 0 | W11: 600000 | X11: 0 | Y11: 0 | Z11: 0 | AA11: 0 | AD11: 0 | AM11: Z512-M | AN11: R18131-MEIBAN MICRO | AP11: 0 | AQ11: 0 | AR11: 0 | AS11: 0 | AT11: 0 | AU11: 0 | AY11: No | AZ11: W662488 | BA11: 0 | BC11: R18131-MEIBAN MICRO | BF11: S0354833
A12: W0676697 | B12: 10000 | C12: 10000 | D12: 45719 | E12: 502LAUGH | F12: 5:20:26 pm | G12: J00T40070 | I12: 1 | J12: Yes | K12: 73 | L12: PM59 | M12: 10500 | P12: 45719 | R12: 8 | S12: 84000 | T12: PE | U12: R001-41074 REV1.0001 | V12: 0 | W12: 84000 | X12: 0 | Y12: 0 | Z12: 0 | AA12: 0 | AD12: 0 | AM12: R001-41074 REV1.0 | AN12: R18131 | AP12: 0 | AQ12: 0 | AR12: 0 | AS12: 0 | AT12: 0 | AU12: 0 | AY12: No | AZ12: W661927 | BA12: 0 | BC12: R18131 | BF12: S0354948
A13: W0676972 | B13: 10000 | C13: 10000 | D13: 45719 | E13: 505KANGHS | F13: 8:35:45 am | G13: SG-5630465 | I13: 1 | J13: Yes | K13: 59 | L13: PM09 | M13: 4150 | P13: 45719 | R13: 2 | S13: 8300 | T13: PE | U13: 112887240001 | V13: 0 | W13: 8300 | X13: 0 | Y13: 0 | Z13: 0 | AA13: 0 | AD13: 0 | AM13: 11288724 | AN13: I09180-US | AP13: 0 | AQ13: 0 | AR13: 0 | AS13: 0 | AT13: 0 | AU13: 0 | AY13: No | AZ13: W661929 | BA13: 0 | BC13: I09180-US | BF13: S0355330
A14: W0677057 | B14: 10000 | C14: 10000 | D14: 45728 | E14: 502LAUGH | F14: 8:47:17 am | G14: 1000221/1000219/80116793/1012643/XHX24A13A0809/XHX2412190201 | I14: 1 | J14: Yes | K14: 103N | L14: PM41 | M14: 39375 | P14: 45719 | R14: 8 | S14: 315000 | T14: PE | U14: MT273730001 | V14: 0 | W14: 315000 | X14: 0 | Y14: 0 | Z14: 0 | AA14: 0 | AD14: 0 | AM14: MT27373 | AN14: Z26002 | AP14: 0 | AQ14: 0 | AR14: 0 | AS14: 0 | AT14: 0 | AU14: 0 | AY14: No | AZ14: W662937 | BA14: 0 | BC14: Z26002 | BF14: S0355389
A15: W0678631 | B15: 10000 | C15: 30000 | D15: 45719 | E15: 502LAUGH | F15: 1:07:37 pm | G15: 10639931080/10639931079 | I15: 3 | J15: Yes | K15: 85 | L15: QM78 | M15: 36364 | P15: 45719 | R15: 11 | S15: 400004 | T15: PE | U15: 3YM56-80009-FT0001 | V15: 0 | W15: 400000 | X15: 4 | Y15: 0 | Z15: 0 | AA15: 0 | AD15: 0 | AM15: 3YM56-80009-FT | AN15: H08031-JIM-M | AP15: 0 | AQ15: 0 | AR15: 0 | AS15: 0 | AT15: 0 | AU15: 0 | AY15: No | AZ15: W662413 | BA15: 0 | BC15: H08031-JIM-M | BF15: S0357398
A16: W0678841 | B16: 10000 | C16: 30000 | D16: 45719 | E16: 502LAUGH | F16: 0.46189815 | G16: D007Y0330 | I16: 3 | J16: Yes | K16: 101 | L16: QM54 | M16: 6667 | P16: 45719 | R16: 3 | S16: 20001 | T16: PE | U16: 1VV05-80009-FT0001 | V16: 0 | W16: 20000 | X16: 1 | Y16: 0 | Z16: 0 | AA16: 0 | AD16: 0 | AM16: 1VV05-80009-FT | AN16: H08031-JIM-M | AP16: 0 | AQ16: 0 | AR16: 0 | AS16: 0 | AT16: 0 | AU16: 0 | AY16: No | AZ16: W661960 | BA16: 0 | BC16: H08031-JIM-M | BF16: S0357549
A17: W0679142 | B17: 10000 | C17: 10000 | D17: 45719 | E17: 502LAUGH | F17: 5:16:47 pm | G17: SG-5637720-01 | I17: 1 | J17: Yes | K17: 82 | L17: PM11 | M17: 6667 | P17: 45719 | R17: 15 | S17: 100005 | T17: PE | U17: BL-63.5X30MM0001 | V17: 0 | W17: 100000 | X17: 5 | Y17: 0 | Z17: 0 | AA17: 0 | AD17: 0 | AM17: M10009SGT | AN17: B02083 | AP17: 0 | AQ17: 0 | AR17: 0 | AS17: 0 | AT17: 0 | AU17: 0 | AY17: No | AZ17: W662148 | BA17: 0 | BC17: B02083 | BF17: S0357815
A18: W0679255 | B18: 10000 | C18: 10000 | D18: 45720 | E18: 502LAUGH | F18: 8:53:37 am | G18: 4103023U5 | I18: 1 | J18: Yes | K18: 46 | L18: PS66 | M18: 3000 | P18: 45719 | R18: 1 | S18: 3000 | T18: PE | U18: 250-6174-000001 | V18: 0 | W18: 3000 | X18: 0 | Y18: 0 | Z18: 0 | AA18: 0 | AD18: 0 | AM18: 250-6174-00 | AN18: J10025 | AP18: 0 | AQ18: 0 | AR18: 0 | AS18: 0 | AT18: 0 | AU18: 0 | AY18: No | AZ18: W662149 | BA18: 0 | BC18: J10025 | BF18: S0357887
A19: W0679262 | B19: 10000 | C19: 10000 | D19: 45719 | E19: 502LAUGH | F19: 5:18:29 pm | G19: 4103018U5A | I19: 1 | J19: Yes | K19: 46 | L19: PS66 | M19: 4000 | P19: 45719 | R19: 1 | S19: 4000 | T19: PE | U19: 260-6407-000001 | V19: 0 | W19: 4000 | X19: 0 | Y19: 0 | Z19: 0 | AA19: 0 | AD19: 0 | AM19: 260-6407-00 | AN19: J10025 | AP19: 0 | AQ19: 0 | AR19: 0 | AS19: 0 | AT19: 0 | AU19: 0 | AY19: No | AZ19: W662153 | BA19: 0 | BC19: J10025 | BF19: S0357888
A20: W0679320 | B20: 10000 | C20: 20000 | D20: 45719 | E20: 505KANGHS | F20: 8:34:54 am | G20: 4103001U5/4103002U5 | I20: 1 | J20: Yes | K20: 94 | L20: PS19 | M20: 3000 | P20: 45719 | R20: 4 | S20: 12000 | T20: PE | U20: 0B49100 REVAA0001 | V20: 0 | W20: 6000 | X20: 6000 | Y20: 0 | Z20: 0 | AA20: 0 | AD20: 0 | AM20: 0B49100 REVAA | AN20: W23041-TH | AP20: 0 | AQ20: 0 | AR20: 0 | AS20: 0 | AT20: 0 | AU20: 0 | AY20: No | AZ20: W662434 | BA20: 0 | BC20: W23041-TH | BF20: H0064549
A21: W0679327 | B21: 10000 | C21: 30000 | D21: 45719 | E21: 502LAUGH | F21: 0.46121528 | G21: D007Y0330 | I21: 3 | J21: Yes | K21: 101 | L21: QM54 | M21: 6667 | P21: 45719 | R21: 3 | S21: 20001 | T21: PE | U21: 1VV04-80009-FT0001 | V21: 0 | W21: 20000 | X21: 1 | Y21: 0 | Z21: 0 | AA21: 0 | AD21: 0 | AM21: 1VV04-80009-FT | AN21: H08031-JIM-M | AP21: 0 | AQ21: 0 | AR21: 0 | AS21: 0 | AT21: 0 | AU21: 0 | AY21: No | AZ21: W661974 | BA21: 0 | BC21: H08031-JIM-M | BF21: S0358004
A22: W0679360 | B22: 10000 | C22: 30000 | D22: 45720 | E22: 502LAUGH | F22: 8:37:07 am | G22: D005I8320/D00676710 | I22: 3 | J22: Yes | K22: 101 | L22: QM54 | M22: 34667 | P22: 45719 | R22: 3 | S22: 104001 | T22: PE | U22: 6ZE06-80002-FT0001 | V22: 0 | W22: 100000 | X22: 4001 | Y22: 0 | Z22: 0 | AA22: 0 | AD22: 0 | AM22: 6ZE06-80002-FT | AN22: H08031-JIM-M | AP22: 0 | AQ22: 0 | AR22: 0 | AS22: 0 | AT22: 0 | AU22: 0 | AY22: No | AZ22: W662154 | BA22: 0 | BC22: H08031-JIM-M | BF22: S0358096
A23: W0679373 | B23: 10000 | C23: 30000 | D23: 45720 | E23: 502LAUGH | F23: 0.46773148 | G23: 10639931093 | I23: 3 | J23: Yes | K23: 85 | L23: QM78 | M23: 5455 | P23: 45719 | R23: 11 | S23: 60005 | T23: PE | U23: B7RT9-80001-FT0001 | V23: 0 | W23: 50000 | X23: 10005 | Y23: 0 | Z23: 0 | AA23: 0 | AD23: 0 | AM23: B7RT9-80001-FT | AN23: H08031-JIM-M | AP23: 0 | AQ23: 0 | AR23: 0 | AS23: 0 | AT23: 0 | AU23: 0 | AY23: No | AZ23: W662500 | BA23: 0 | BC23: H08031-JIM-M | BF23: S0358100
A24: W0679521 | B24: 10000 | C24: 30000 | D24: 45719 | E24: 502LAUGH | F24: 3:36:54 pm | G24: D00676710/D005I8320 | I24: 3 | J24: Yes | K24: 101 | L24: QM54 | M24: 60000 | P24: 45719 | R24: 3 | S24: 180000 | T24: PE | U24: 6ZE04-80002-FT0001 | V24: 0 | W24: 175000 | X24: 5000 | Y24: 0 | Z24: 0 | AA24: 0 | AD24: 0 | AM24: 6ZE04-80002-FT | AN24: H08031-JIM-M | AP24: 0 | AQ24: 0 | AR24: 0 | AS24: 0 | AT24: 0 | AU24: 0 | AY24: No | AZ24: W662155 | BA24: 0 | BC24: H08031-JIM-M | BF24: S0358297
A25: W0679577 | B25: 10000 | C25: 10000 | D25: 45720 | E25: 502LAUGH | F25: 3:57:09 pm | G25: M4B4603BGJAJ123-S248100296/E0531904 | I25: 1 | J25: Yes | K25: 67 | L25: PM42 | M25: 10000 | P25: 45719 | R25: 1 | S25: 10000 | T25: PE | U25: 716626800 REVC0001 | V25: 0 | W25: 10000 | X25: 0 | Y25: 0 | Z25: 0 | AA25: 0 | AD25: 0 | AM25: 716626800 REVC | AN25: S19314 | AP25: 0 | AQ25: 0 | AR25: 0 | AS25: 0 | AT25: 0 | AU25: 0 | AY25: No | AZ25: W662440 | BA25: 0 | BC25: S19314 | BF25: H0064581
A26: W0679577 | B26: 10000 | C26: 20000 | D26: 45720 | E26: 502LAUGH | F26: 3:57:09 pm | G26: M4B4603BGJAJ123-S248100296/E0531904 | I26: 1 | J26: Yes | K26: 66 | L26: PMJ0 | M26: 50000 | P26: 45719 | R26: 1 | S26: 50000 | T26: PE | U26: 716626800 REVC0001 | V26: 0 | W26: 50000 | X26: 0 | Y26: 0 | Z26: 0 | AA26: 0 | AD26: 0 | AM26: 716626800 REVC | AN26: S19314 | AP26: 0 | AQ26: 0 | AR26: 0 | AS26: 0 | AT26: 0 | AU26: 0 | AY26: No | AZ26: W662440 | BA26: 0 | BC26: S19314 | BF26: H0064581
A27: W0679615 | B27: 10000 | C27: 10000 | D27: 45720 | E27: 502LAUGH | F27: 0.42090278 | G27: 4067S1 | I27: 1 | J27: Yes | K27: 78 | L27: PM84 | M27: 5000 | P27: 45719 | R27: 2 | S27: 10000 | T27: PE | U27: 712730 REV1000001 | V27: 0 | W27: 10000 | X27: 0 | Y27: 0 | Z27: 0 | AA27: 0 | AD27: 0 | AM27: 712730 REV402 | AN27: V22000 | AP27: 0 | AQ27: 0 | AR27: 0 | AS27: 0 | AT27: 0 | AU27: 0 | AY27: No | AZ27: W662156 | BA27: 0 | BC27: V22000 | BF27: S0358336
A28: W0679648 | B28: 10000 | C28: 50000 | D28: 45720 | E28: 502LAUGH | F28: 4:00:35 pm | G28: M4B4603BGJAJ119-S248100138/E0531904 | I28: 1 | J28: Yes | K28: 66 | L28: PMJ0 | M28: 5000 | P28: 45719 | R28: 1 | S28: 5000 | T28: PE | U28: 716626800 REVC0001 | V28: 0 | W28: 5000 | X28: 0 | Y28: 0 | Z28: 0 | AA28: 0 | AD28: 0 | AM28: 716626800 REVC | AN28: S19081-TH | AP28: 0 | AQ28: 0 | AR28: 0 | AS28: 0 | AT28: 0 | AU28: 0 | AY28: No | AZ28: W662013 | BA28: 0 | BC28: S19081-TH | BF28: H0064608
A29: W0679649 | B29: 10000 | C29: 10000 | D29: 45722 | E29: 502LAUGH | F29: 1:40:04 pm | G29: M4B4603BGJAJ119-S248100138/E0531904 | I29: 1 | J29: Yes | K29: 67N | L29: PM42 | M29: 120000 | P29: 45719 | R29: 1 | S29: 120000 | T29: PE | U29: 716626800 REVC0001 | V29: 0 | W29: 120000 | X29: 0 | Y29: 0 | Z29: 0 | AA29: 0 | AD29: 0 | AM29: 716626800 REVC | AN29: S19081-TH | AP29: 0 | AQ29: 0 | AR29: 0 | AS29: 0 | AT29: 0 | AU29: 0 | AY29: No | AZ29: W662445 | BA29: 0 | BC29: S19081-TH | BF29: H0064609
A30: W0679651 | B30: 10000 | C30: 10000 | D30: 45720 | E30: 502LAUGH | F30: 4:02:10 pm | G30: 5304412-01-02-01/5304412-01-05-06/5304412-01-05-04 | I30: 1 | J30: Yes | K30: 90 | L30: PM35 | M30: 29700 | P30: 45719 | R30: 2 | S30: 59400 | T30: PE | U30: 723852900-PROTO 0001 | V30: 0 | W30: 59400 | X30: 0 | Y30: 0 | Z30: 0 | AA30: 0 | AD30: 0 | AM30: 723852900-PROTO D | AN30: S19081-TH | AP30: 0 | AQ30: 0 | AR30: 0 | AS30: 0 | AT30: 0 | AU30: 0 | AY30: No | AZ30: W662207 | BA30: 0 | BC30: S19081-TH | BF30: H0064611
A31: W0679651 | B31: 10000 | C31: 20000 | D31: 45720 | E31: 502LAUGH | F31: 4:02:10 pm | G31: 5304412-01-02-01/5304412-01-05-06/5304412-01-05-04 | I31: 1 | J31: Yes | K31: 90 | L31: QC04 | M31: 24300 | P31: 45719 | R31: 2 | S31: 48600 | T31: PE | U31: 723852900-PROTO 0001 | V31: 0 | W31: 48600 | X31: 0 | Y31: 0 | Z31: 0 | AA31: 0 | AD31: 0 | AM31: 723852900-PROTO D | AN31: S19081-TH | AP31: 0 | AQ31: 0 | AR31: 0 | AS31: 0 | AT31: 0 | AU31: 0 | AY31: No | AZ31: W662207 | BA31: 0 | BC31: S19081-TH | BF31: H0064611
A32: W0679667 | B32: 10000 | C32: 10000 | D32: 45721 | E32: 502LAUGH | F32: 8:57:08 am | G32: E0801904/M0BSO4470 | I32: 1 | J32: Yes | K32: 87 | L32: PM14 | M32: 20250 | P32: 45719 | R32: 2 | S32: 40500 | T32: PE | U32: 762070100 REVA0001 | V32: 0 | W32: 40500 | X32: 0 | Y32: 0 | Z32: 0 | AA32: 0 | AD32: 0 | AM32: 762070100 REVA | AN32: S19081-TH | AP32: 0 | AQ32: 0 | AR32: 0 | AS32: 0 | AT32: 0 | AU32: 0 | AY32: No | AZ32: W662448 | BA32: 0 | BC32: S19081-TH | BF32: H0064624
A33: W0679682 | B33: 10000 | C33: 10000 | D33: 45719 | E33: 502LAUGH | F33: 5:36:36 pm | G33: SG-5630465 | I33: 1 | J33: Yes | K33: 59 | L33: PM09 | M33: 1660 | P33: 45719 | R33: 2 | S33: 3320 | T33: PE | U33: 112887240001 | V33: 0 | W33: 3320 | X33: 0 | Y33: 0 | Z33: 0 | AA33: 0 | AD33: 0 | AM33: 11288724 | AN33: I09180 | AP33: 0 | AQ33: 0 | AR33: 0 | AS33: 0 | AT33: 0 | AU33: 0 | AY33: No | AZ33: W662015 | BA33: 0 | BC33: I09180 | BF33: S0358357
A34: W0679682 | B34: 20000 | C34: 10000 | D34: 45719 | E34: 502LAUGH | F34: 5:36:36 pm | G34: SG-5630465 | I34: 1 | J34: Yes | K34: 59 | L34: PM09 | M34: 1245 | P34: 45719 | R34: 2 | S34: 2490 | T34: PE | U34: 112887240001 | V34: 0 | W34: 2490 | X34: 0 | Y34: 0 | Z34: 0 | AA34: 0 | AD34: 0 | AM34: 11288724 | AN34: I09180 | AP34: 0 | AQ34: 0 | AR34: 0 | AS34: 0 | AT34: 0 | AU34: 0 | AY34: No | AZ34: W662015 | BA34: 0 | BC34: I09180 | BF34: S0358357
A35: W0679689 | B35: 10000 | C35: 10000 | D35: 45719 | E35: 502LAUGH | F35: 1:06:29 pm | G35: SG-5622228 01 | I35: 1 | J35: Yes | K35: 59 | L35: PM09 | M35: 860 | P35: 45719 | R35: 1 | S35: 860 | T35: PE | U35: 150034910001 | V35: 0 | W35: 860 | X35: 0 | Y35: 0 | Z35: 0 | AA35: 0 | AD35: 0 | AM35: 15003491 | AN35: I09180 | AP35: 0 | AQ35: 0 | AR35: 0 | AS35: 0 | AT35: 0 | AU35: 0 | AY35: No | AZ35: W662017 | BA35: 0 | BC35: I09180 | BF35: S0358364
A36: W0679689 | B36: 20000 | C36: 10000 | D36: 45719 | E36: 502LAUGH | F36: 1:06:29 pm | G36: SG-5622228 01 | I36: 1 | J36: Yes | K36: 59 | L36: PM09 | M36: 860 | P36: 45719 | R36: 1 | S36: 860 | T36: PE | U36: 150034910001 | V36: 0 | W36: 860 | X36: 0 | Y36: 0 | Z36: 0 | AA36: 0 | AD36: 0 | AM36: 15003491 | AN36: I09180 | AP36: 0 | AQ36: 0 | AR36: 0 | AS36: 0 | AT36: 0 | AU36: 0 | AY36: No | AZ36: W662017 | BA36: 0 | BC36: I09180 | BF36: S0358364
A37: W0679709 | B37: 10000 | C37: 20000 | D37: 45721 | E37: 502LAUGH | F37: 8:32:17 am | G37: L4015U8016 | I37: 2 | J37: Yes | K37: 92 | L37: PM87 | M37: 8300 | P37: 45719 | R37: 1 | S37: 8300 | T37: PE | U37: 150-015580001 | V37: 0 | W37: 8000 | X37: 300 | Y37: 0 | Z37: 0 | AA37: 0 | AD37: 0 | AM37: 150-01558 | AN37: I09146 | AP37: 0 | AQ37: 0 | AR37: 0 | AS37: 0 | AT37: 0 | AU37: 0 | AY37: No | AZ37: W662208 | BA37: 0 | BC37: I09146 | BF37: S0358386
A38: W0679822 | B38: 10000 | C38: 30000 | D38: 45720 | E38: 502LAUGH | F38: 8:38:39 am | G38: 10620258086/10620258088 | I38: 3 | J38: Yes | K38: 85 | L38: QM78 | M38: 10000 | P38: 45719 | R38: 11 | S38: 110000 | T38: PE | U38: 7FP43-80004-FT0001 | V38: 0 | W38: 100000 | X38: 10000 | Y38: 0 | Z38: 0 | AA38: 0 | AD38: 0 | AM38: 7FP43-80004-FT | AN38: H08031-JIM-M | AP38: 0 | AQ38: 0 | AR38: 0 | AS38: 0 | AT38: 0 | AU38: 0 | AY38: No | AZ38: W662159 | BA38: 0 | BC38: H08031-JIM-M | BF38: S0358453
A39: W0679830 | B39: 10000 | C39: 20000 | D39: 45720 | E39: 502LAUGH | F39: 4:37:49 pm | G39: D007Y0330/D006A5780 | I39: 2 | J39: Yes | K39: 77 | L39: PM74 | M39: 21300 | P39: 45719 | R39: 10 | S39: 213000 | T39: PE | U39: 6ZE08-80002-FT0001 | V39: 0 | W39: 200000 | X39: 13000 | Y39: 0 | Z39: 0 | AA39: 0 | AD39: 0 | AM39: 6ZE08-80002-FT | AN39: H08031-JIM-M | AP39: 0 | AQ39: 0 | AR39: 0 | AS39: 0 | AT39: 0 | AU39: 0 | AY39: No | AZ39: W662210 | BA39: 0 | BC39: H08031-JIM-M | BF39: S0358461
A40: W0679833 | B40: 10000 | C40: 10000 | D40: 45719 | E40: 502LAUGH | F40: 3:38:07 pm | G40: M0BG16901 | I40: 1 | J40: Yes | K40: 78 | L40: PM84 | M40: 1000 | P40: 45719 | R40: 1 | S40: 1000 | T40: PE | U40: 86.E8260001 | V40: 0 | W40: 1000 | X40: 0 | Y40: 0 | Z40: 0 | AA40: 0 | AD40: 0 | AM40: 86.E826 | AN40: T20390-PMI | AP40: 0 | AQ40: 0 | AR40: 0 | AS40: 0 | AT40: 0 | AU40: 0 | AY40: No | AZ40: W662160 | BA40: 0 | BC40: T20390-PMI | BF40: S0358470
A41: W0679841 | B41: 10000 | C41: 10000 | D41: 45719 | E41: 502LAUGH | F41: 3:38:08 pm | G41: M0BG16901 | I41: 1 | J41: Yes | K41: 78 | L41: PM84 | M41: 50 | P41: 45719 | R41: 1 | S41: 50 | T41: PE | U41: 86.E8260001 | V41: 0 | W41: 50 | X41: 0 | Y41: 0 | Z41: 0 | AA41: 0 | AD41: 0 | AM41: 86.E826 | AN41: T20390-PMI | AP41: 0 | AQ41: 0 | AR41: 0 | AS41: 0 | AT41: 0 | AU41: 0 | AY41: No | AZ41: W662027 | BA41: 0 | BC41: T20390-PMI | BF41: ZSA101740
...

Sheet 4-Mar
A1: Production Output
A2: Filter: Date Completed: 04/03/25
A4: Work Order No. | B4: Work Order Line No. | C4: WO Journal Line No. | D4: Add Date | E4: Add User | F4: Add Time | G4: Material Batch No. | H4: Die Cut | I4: Process No. | J4: Posted | K4: Machine Code | L4: Staff Code | M4: No. of Press | N4: Date Started | O4: Time Started | P4: Date Completed | Q4: Time Completed | R4: No. of Ups | S4: Printed Quantity | T4: Journal Type | U4: Item Code | V4: Quantity | W4: QC Approved Quantity | X4: Rejected Quantity | Y4: Roll | Z4: Length | AA4: Width | AB4: Length UOM | AC4: Width UOM | AD4: RM Quantity | AE4: Material Code | AF4: Variant Code | AG4: Request Delivery Date | AH4: Non QC Record | AI4: Link to Line No. | AJ4: Related | AK4: Expire Date | AL4: Label Remark | AM4: Customer Part Number | AN4: Customer Code | AO4: ddmm | AP4: Label Packing Quantity 1 | AQ4: Label Quantity 1 | AR4: Label Packing Quantity 2 | AS4: Label Quantity 2 | AT4: Label Packing Quantity 3 | AU4: Label Quantity 3 | AV4: UOM for Label Printing | AW4: QC Inspector | AX4: Summarised Period | AY4: Summarised | AZ4: Posted Work Order No. | BA4: Colour | BB4: Currency | BC4: Ref Customer | BD4: Group | BE4: PO | BF4: Source Doc. No.
A5: W0675393 | B5: 10000 | C5: 30000 | D5: 45730 | E5: 502LAUGH | F5: 8:40:59 am | G5: 10639931075/10639931076/10639931074/10639931073/10639931072 | I5: 2 | J5: Yes | K5: 86 | L5: PM45 | M5: 29800 | P5: 45720 | R5: 36 | S5: 1072800 | T5: PE | U5: 5180-0101-BH2120001 | V5: 0 | W5: 1000000 | X5: 72800 | Y5: 0 | Z5: 0 | AA5: 0 | AD5: 0 | AM5: 5180-0101-BH212 | AN5: H08031-JIM | AP5: 0 | AQ5: 0 | AR5: 0 | AS5: 0 | AT5: 0 | AU5: 0 | AY5: No | AZ5: W662930 | BA5: 0 | BC5: H08031-JIM | BF5: S0353198
A6: W0677057 | B6: 10000 | C6: 20000 | D6: 45728 | E6: 502LAUGH | F6: 8:47:17 am | G6: 1000221/1000219/80116793/1012643/XHX24A13A0809/XHX2412190201 | I6: 1 | J6: Yes | K6: 103N | L6: PM55 | M6: 35000 | P6: 45720 | R6: 8 | S6: 280000 | T6: PE | U6: MT273730001 | V6: 0 | W6: 280000 | X6: 0 | Y6: 0 | Z6: 0 | AA6: 0 | AD6: 0 | AM6: MT27373 | AN6: Z26002 | AP6: 0 | AQ6: 0 | AR6: 0 | AS6: 0 | AT6: 0 | AU6: 0 | AY6: No | AZ6: W662937 | BA6: 0 | BC6: Z26002 | BF6: S0355389
A7: W0677057 | B7: 10000 | C7: 30000 | D7: 45728 | E7: 502LAUGH | F7: 8:47:17 am | G7: 1000221/1000219/80116793/1012643/XHX24A13A0809/XHX2412190201 | I7: 1 | J7: Yes | K7: 103 | L7: PM47 | M7: 15625 | P7: 45720 | R7: 8 | S7: 125000 | T7: PE | U7: MT273730001 | V7: 0 | W7: 125000 | X7: 0 | Y7: 0 | Z7: 0 | AA7: 0 | AD7: 0 | AM7: MT27373 | AN7: Z26002 | AP7: 0 | AQ7: 0 | AR7: 0 | AS7: 0 | AT7: 0 | AU7: 0 | AY7: No | AZ7: W662937 | BA7: 0 | BC7: Z26002 | BF7: S0355389
A8: W0677057 | B8: 20000 | C8: 10000 | D8: 45728 | E8: 502LAUGH | F8: 8:47:17 am | G8: 1000221/1000219/80116793/1012643/XHX24A13A0809/XHX2412190201 | I8: 1 | J8: Yes | K8: 103 | L8: PM47 | M8: 43125 | P8: 45720 | R8: 8 | S8: 345000 | T8: PE | U8: MT273730001 | V8: 0 | W8: 345000 | X8: 0 | Y8: 0 | Z8: 0 | AA8: 0 | AD8: 0 | AM8: MT27373 | AN8: Z26002 | AP8: 0 | AQ8: 0 | AR8: 0 | AS8: 0 | AT8: 0 | AU8: 0 | AY8: No | AZ8: W662937 | BA8: 0 | BC8: Z26002 | BF8: S0355389
A9: W0678411 | B9: 10000 | C9: 10000 | D9: 45728 | E9: 502LAUGH | F9: 8:38:10 am | G9: SG-564141001 | I9: 1 | J9: Yes | K9: 73N | L9: PM18 | M9: 60000 | P9: 45720 | R9: 12 | S9: 720000 | T9: PE | U9: 80256230001 | V9: 0 | W9: 720000 | X9: 0 | Y9: 0 | Z9: 0 | AA9: 0 | AD9: 0 | AM9: 8025623 | AN9: B02083 | AP9: 0 | AQ9: 0 | AR9: 0 | AS9: 0 | AT9: 0 | AU9: 0 | AY9: No | AZ9: W663295 | BA9: 0 | BC9: B02083 | BF9: S0357132
A10: W0678680 | B10: 10000 | C10: 20000 | D10: 45721 | E10: 502LAUGH | F10: 8:38:39 am | G10: 4067S1 | I10: 1 | J10: Yes | K10: 12 | L10: PP05 | M10: 5000 | P10: 45720 | R10: 1 | S10: 5000 | T10: PE | U10: 710922 INDEX1020001 | V10: 0 | W10: 5000 | X10: 0 | Y10: 0 | Z10: 0 | AA10: 0 | AD10: 0 | AM10: 710922 INDEX404 | AN10: V22000 | AP10: 0 | AQ10: 0 | AR10: 0 | AS10: 0 | AT10: 0 | AU10: 0 | AY10: No | AZ10: W662142 | BA10: 0 | BC10: V22000 | BF10: S0357443
A11: W0678697 | B11: 10000 | C11: 10000 | D11: 45720 | E11: 502LAUGH | F11: 5:39:52 pm | G11: SG-5622228 01 | I11: 1 | J11: Yes | K11: 59 | L11: PS74 | M11: 10000 | P11: 45720 | R11: 6 | S11: 60000 | T11: PE | U11: 15058365 REVB0001 | V11: 0 | W11: 60000 | X11: 0 | Y11: 0 | Z11: 0 | AA11: 0 | AD11: 0 | AM11: 15058365 REVB | AN11: I09180-US | AP11: 0 | AQ11: 0 | AR11: 0 | AS11: 0 | AT11: 0 | AU11: 0 | AY11: No | AZ11: W662143 | BA11: 0 | BC11: I09180-US | BF11: S0357462
A12: W0678767 | B12: 10000 | C12: 10000 | D12: 45721 | E12: 502LAUGH | F12: 0.48003472 | G12: 4103023U5 | I12: 1 | J12: Yes | K12: 46 | L12: PS66 | M12: 27000 | P12: 45720 | R12: 1 | S12: 27000 | T12: PE | U12: 250-6174-000001 | V12: 0 | W12: 27000 | X12: 0 | Y12: 0 | Z12: 0 | AA12: 0 | AD12: 0 | AM12: 250-6174-00 | AN12: J10025-PHL-SG | AP12: 0 | AQ12: 0 | AR12: 0 | AS12: 0 | AT12: 0 | AU12: 0 | AY12: No | AZ12: W662420 | BA12: 0 | BC12: J10025-PHL-SG | BF12: S0357505
A13: W0679218 | B13: 10000 | C13: 20000 | D13: 45720 | E13: 502LAUGH | F13: 2:06:32 pm | G13: 10639931058/10639931057 | I13: 1 | J13: Yes | K13: 82 | L13: PM11 | M13: 5143 | P13: 45720 | R13: 140 | S13: 720020 | T13: PE | U13: 1F3Y1-400110001 | V13: 0 | W13: 720000 | X13: 20 | Y13: 0 | Z13: 0 | AA13: 0 | AD13: 0 | AM13: 1F3Y1-40011 | AN13: H08031-NKG THAI-HPP | AP13: 0 | AQ13: 0 | AR13: 0 | AS13: 0 | AT13: 0 | AU13: 0 | AY13: No | AZ13: W662492 | BA13: 0 | BC13: H08031-NKG THAI-HPP | BF13: S0357872
A14: W0679220 | B14: 10000 | C14: 30000 | D14: 45723 | E14: 502LAUGH | F14: 5:25:12 pm | G14: BXB022-02 | I14: 1 | J14: Yes | K14: 90 | L14: PM35 | M14: 11000 | P14: 45720 | R14: 4 | S14: 44000 | T14: PE | U14: Y00-0000928-000001 | V14: 0 | W14: 44000 | X14: 0 | Y14: 0 | Z14: 0 | AA14: 0 | AD14: 0 | AM14: 300-0000396-00 | AN14: F06170-JIANGSU | AP14: 0 | AQ14: 0 | AR14: 0 | AS14: 0 | AT14: 0 | AU14: 0 | AY14: No | AZ14: W662433 | BA14: 0 | BC14: F06170-JIANGSU | BF14: S0357841
A15: W0679220 | B15: 10000 | C15: 40000 | D15: 45723 | E15: 502LAUGH | F15: 5:25:12 pm | G15: BXB022-02 | I15: 1 | J15: Yes | K15: 90N | L15: QC04 | M15: 6500 | P15: 45720 | R15: 4 | S15: 26000 | T15: PE | U15: Y00-0000928-000001 | V15: 0 | W15: 26000 | X15: 0 | Y15: 0 | Z15: 0 | AA15: 0 | AD15: 0 | AM15: 300-0000396-00 | AN15: F06170-JIANGSU | AP15: 0 | AQ15: 0 | AR15: 0 | AS15: 0 | AT15: 0 | AU15: 0 | AY15: No | AZ15: W662433 | BA15: 0 | BC15: F06170-JIANGSU | BF15: S0357841
A16: W0679330 | B16: 10000 | C16: 20000 | D16: 45721 | E16: 502LAUGH | F16: 2:04:01 pm | G16: 10639931010 | I16: 2 | J16: Yes | K16: 77 | L16: PM74 | M16: 1705 | P16: 45720 | R16: 88 | S16: 150040 | T16: PE | U16: 6ZD61-800010001 | V16: 0 | W16: 140000 | X16: 10040 | Y16: 0 | Z16: 0 | AA16: 0 | AD16: 0 | AM16: 6ZD61-80001 | AN16: H08031-JIM-M | AP16: 0 | AQ16: 0 | AR16: 0 | AS16: 0 | AT16: 0 | AU16: 0 | AY16: No | AZ16: W662494 | BA16: 0 | BC16: H08031-JIM-M | BF16: S0358007
A17: W0679332 | B17: 10000 | C17: 20000 | D17: 45721 | E17: 502LAUGH | F17: 0.45700231 | G17: 10639931094/10639931096 | I17: 2 | J17: Yes | K17: 77 | L17: PM74 | M17: 4807 | P17: 45720 | R17: 88 | S17: 423016 | T17: PE | U17: 3YM56-80009-FT0001 | V17: 0 | W17: 440000 | X17: -16984 | Y17: 0 | Z17: 0 | AA17: 0 | AD17: 0 | AM17: 3YM56-80009-FT | AN17: H08031-JIM-M | AP17: 0 | AQ17: 0 | AR17: 0 | AS17: 0 | AT17: 0 | AU17: 0 | AY17: No | AZ17: W662496 | BA17: 0 | BC17: H08031-JIM-M | BF17: S0358010
A18: W0679350 | B18: 10000 | C18: 20000 | D18: 45722 | E18: 502LAUGH | F18: 8:34:27 am | G18: 10639931012/10639931010 | I18: 2 | J18: Yes | K18: 77 | L18: PM74 | M18: 2500 | P18: 45720 | R18: 88 | S18: 220000 | T18: PE | U18: N9K05-80021-FT0001 | V18: 0 | W18: 200000 | X18: 20000 | Y18: 0 | Z18: 0 | AA18: 0 | AD18: 0 | AM18: N9K05-80021-FT | AN18: H08031-JIM-M | AP18: 0 | AQ18: 0 | AR18: 0 | AS18: 0 | AT18: 0 | AU18: 0 | AY18: No | AZ18: W662437 | BA18: 0 | BC18: H08031-JIM-M | BF18: S0358090
A19: W0679522 | B19: 10000 | C19: 20000 | D19: 45722 | E19: 502LAUGH | F19: 8:35:19 am | G19: 10639931010 | I19: 2 | J19: Yes | K19: 77 | L19: PM74 | M19: 1250 | P19: 45720 | R19: 88 | S19: 110000 | T19: PE | U19: N9K05-80021-FT0001 | V19: 0 | W19: 100000 | X19: 10000 | Y19: 0 | Z19: 0 | AA19: 0 | AD19: 0 | AM19: N9K05-80021-FT | AN19: H08031-JIM-M | AP19: 0 | AQ19: 0 | AR19: 0 | AS19: 0 | AT19: 0 | AU19: 0 | AY19: No | AZ19: W662501 | BA19: 0 | BC19: H08031-JIM-M | BF19: S0358298
A20: W0679640 | B20: 10000 | C20: 10000 | D20: 45722 | E20: 502LAUGH | F20: 8:56:01 am | G20: M0BUE5340/M0BTD2082 | I20: 1 | J20: Yes | K20: 70 | L20: PS84 | M20: 10000 | P20: 45720 | R20: 6 | S20: 60000 | T20: PE | U20: 100595138 REVB0001 | V20: 0 | W20: 60000 | X20: 0 | Y20: 0 | Z20: 0 | AA20: 0 | AD20: 0 | AM20: 100595138 REVB | AN20: S19081-TH | AP20: 0 | AQ20: 0 | AR20: 0 | AS20: 0 | AT20: 0 | AU20: 0 | AY20: No | AZ20: W662443 | BA20: 0 | BC20: S19081-TH | BF20: H0064600
A21: W0679649 | B21: 10000 | C21: 20000 | D21: 45722 | E21: 502LAUGH | F21: 1:40:04 pm | G21: M4B4603BGJAJ119-S248100138/E0531904 | I21: 1 | J21: Yes | K21: 66 | L21: PM48 | M21: 110000 | P21: 45720 | R21: 1 | S21: 110000 | T21: PE | U21: 716626800 REVC0001 | V21: 0 | W21: 110000 | X21: 0 | Y21: 0 | Z21: 0 | AA21: 0 | AD21: 0 | AM21: 716626800 REVC | AN21: S19081-TH | AP21: 0 | AQ21: 0 | AR21: 0 | AS21: 0 | AT21: 0 | AU21: 0 | AY21: No | AZ21: W662445 | BA21: 0 | BC21: S19081-TH | BF21: H0064609
A22: W0679650 | B22: 10000 | C22: 10000 | D22: 45722 | E22: 502LAUGH | F22: 1:42:08 pm | G22: 12190705006 | I22: 1 | J22: Yes | K22: 68 | L22: PMJ0 | M22: 19000 | P22: 45720 | R22: 2 | S22: 38000 | T22: PE | U22: 719007600 REVA0001 | V22: 0 | W22: 38000 | X22: 0 | Y22: 0 | Z22: 0 | AA22: 0 | AD22: 0 | AM22: 719007600 REVA | AN22: S19081-TH | AP22: 0 | AQ22: 0 | AR22: 0 | AS22: 0 | AT22: 0 | AU22: 0 | AY22: No | AZ22: W662446 | BA22: 0 | BC22: S19081-TH | BF22: H0064610
A23: W0679668 | B23: 10000 | C23: 10000 | D23: 45722 | E23: 502LAUGH | F23: 1:42:36 pm | G23: E0801904/M0BSO4460 | I23: 1 | J23: Yes | K23: 87 | L23: PM14 | M23: 20250 | P23: 45720 | R23: 2 | S23: 40500 | T23: PE | U23: 762070100 REVA0001 | V23: 0 | W23: 40500 | X23: 0 | Y23: 0 | Z23: 0 | AA23: 0 | AD23: 0 | AM23: 762070100 REVA | AN23: S19081-TH | AP23: 0 | AQ23: 0 | AR23: 0 | AS23: 0 | AT23: 0 | AU23: 0 | AY23: No | AZ23: W662449 | BA23: 0 | BC23: S19081-TH | BF23: H0064625
A24: W0679829 | B24: 10000 | C24: 20000 | D24: 45729 | E24: 502LAUGH | F24: 5:02:00 pm | G24: 10639931052 | I24: 1 | J24: Yes | K24: 79 | L24: PM16 | M24: 304 | P24: 45720 | R24: 297 | S24: 90288 | T24: PE | U24: F6U65-80033-FT0001 | V24: 0 | W24: 70000 | X24: 20288 | Y24: 0 | Z24: 0 | AA24: 0 | AD24: 0 | AM24: F6U65-80033-FT | AN24: H08031-JIM-M | AP24: 0 | AQ24: 0 | AR24: 0 | AS24: 0 | AT24: 0 | AU24: 0 | AY24: No | AZ24: W662974 | BA24: 0 | BC24: H08031-JIM-M | BF24: S0358460
A25: W0679830 | B25: 10000 | C25: 30000 | D25: 45720 | E25: 502LAUGH | F25: 4:37:49 pm | G25: D007Y0330/D006A5780 | I25: 3 | J25: Yes | K25: 101 | L25: QM54 | M25: 42000 | P25: 45720 | R25: 3 | S25: 126000 | T25: PE | U25: 6ZE08-80002-FT0001 | V25: 0 | W25: 200000 | X25: -74000 | Y25: 0 | Z25: 0 | AA25: 0 | AD25: 0 | AM25: 6ZE08-80002-FT | AN25: H08031-JIM-M | AP25: 0 | AQ25: 0 | AR25: 0 | AS25: 0 | AT25: 0 | AU25: 0 | AY25: No | AZ25: W662210 | BA25: 0 | BC25: H08031-JIM-M | BF25: S0358461
A26: W0679839 | B26: 10000 | C26: 20000 | D26: 45729 | E26: 502LAUGH | F26: 5:03:33 pm | G26: 10639931052 | I26: 1 | J26: Yes | K26: 79 | L26: PM16 | M26: 337 | P26: 45720 | R26: 297 | S26: 100089 | T26: PE | U26: F6U61-80027-FT0001 | V26: 0 | W26: 80000 | X26: 20089 | Y26: 0 | Z26: 0 | AA26: 0 | AD26: 0 | AM26: F6U61-80027-FT | AN26: H08031-JIM-M | AP26: 0 | AQ26: 0 | AR26: 0 | AS26: 0 | AT26: 0 | AU26: 0 | AY26: No | AZ26: W662975 | BA26: 0 | BC26: H08031-JIM-M | BF26: S0358468
A27: W0679849 | B27: 10000 | C27: 20000 | D27: 45720 | E27: 502LAUGH | F27: 2:07:15 pm | G27: 4103001U5 | I27: 1 | J27: Yes | K27: 94 | L27: PM09 | M27: 500 | P27: 45720 | R27: 4 | S27: 2000 | T27: PE | U27: 0B49230 EC C73490001 | V27: 0 | W27: 2000 | X27: 0 | Y27: 0 | Z27: 0 | AA27: 0 | AD27: 0 | AM27: 0B49230 EC C73494 | AN27: I09082-TL | AP27: 0 | AQ27: 0 | AR27: 0 | AS27: 0 | AT27: 0 | AU27: 0 | AY27: No | AZ27: W662545 | BA27: 0 | BC27: I09082-TL | BF27: H0064636
A28: W0679898 | B28: 10000 | C28: 10000 | D28: 45721 | E28: 502LAUGH | F28: 3:56:44 pm | G28: 411517U5/411520U5 | I28: 1 | J28: Yes | K28: 22 | L28: PS13 | M28: 15000 | P28: 45720 | R28: 2 | S28: 30000 | T28: PE | U28: 250-6253-000001 | V28: 0 | W28: 30000 | X28: 0 | Y28: 0 | Z28: 0 | AA28: 0 | AD28: 0 | AM28: 250-6253-00 | AN28: J10025 | AP28: 0 | AQ28: 0 | AR28: 0 | AS28: 0 | AT28: 0 | AU28: 0 | AY28: No | AZ28: W662548 | BA28: 0 | BC28: J10025 | BF28: S0358481
A29: W0679902 | B29: 10000 | C29: 10000 | D29: 45720 | E29: 502LAUGH | F29: 4:42:12 pm | G29: 4090405U5 | I29: 1 | J29: Yes | K29: 22 | L29: PS13 | M29: 15000 | P29: 45720 | R29: 1 | S29: 15000 | T29: PE | U29: 260-6011-000001 | V29: 0 | W29: 15000 | X29: 0 | Y29: 0 | Z29: 0 | AA29: 0 | AD29: 0 | AM29: 260-6011-00 | AN29: J10025 | AP29: 0 | AQ29: 0 | AR29: 0 | AS29: 0 | AT29: 0 | AU29: 0 | AY29: No | AZ29: W662161 | BA29: 0 | BC29: J10025 | BF29: S0358481
A30: W0679917 | B30: 10000 | C30: 10000 | D30: 45720 | E30: 502LAUGH | F30: 4:39:39 pm | G30: 4111521U5A | I30: 1 | J30: Yes | K30: 61 | L30: PM61 | M30: 8334 | P30: 45720 | R30: 6 | S30: 50004 | T30: PE | U30: 260-6012-000001 | V30: 0 | W30: 50000 | X30: 4 | Y30: 0 | Z30: 0 | AA30: 0 | AD30: 0 | AM30: 260-6012-00 | AN30: J10025 | AP30: 0 | AQ30: 0 | AR30: 0 | AS30: 0 | AT30: 0 | AU30: 0 | AY30: No | AZ30: W662556 | BA30: 0 | BC30: J10025 | BF30: S0358489
A31: W0680064 | B31: 10000 | C31: 10000 | D31: 45720 | E31: 502LAUGH | F31: 4:40:51 pm | G31: 3082510U9 | I31: 1 | J31: Yes | K31: 12 | L31: PP05 | M31: 3000 | P31: 45720 | R31: 1 | S31: 3000 | T31: PE | U31: 107475960001 | V31: 0 | W31: 3000 | X31: 0 | Y31: 0 | Z31: 0 | AA31: 0 | AD31: 0 | AM31: 10747596 | AN31: I09109 | AP31: 0 | AQ31: 0 | AR31: 0 | AS31: 0 | AT31: 0 | AU31: 0 | AY31: No | AZ31: W662165 | BA31: 0 | BC31: I09109 | BF31: S0358738
A32: W0680070 | B32: 10000 | C32: 10000 | D32: 45720 | E32: 502LAUGH | F32: 3:42:17 pm | G32: E041G0470 | I32: 1 | J32: Yes | K32: 78 | L32: PM84 | M32: 4000 | P32: 45720 | R32: 5 | S32: 20000 | T32: PE | U32: 707385 REV1000001 | V32: 0 | W32: 20000 | X32: 0 | Y32: 0 | Z32: 0 | AA32: 0 | AD32: 0 | AM32: 707385 REV401 | AN32: V22000 | AP32: 0 | AQ32: 0 | AR32: 0 | AS32: 0 | AT32: 0 | AU32: 0 | AY32: No | AZ32: W662167 | BA32: 0 | BC32: V22000 | BF32: S0358750
A33: W0680106 | B33: 10000 | C33: 10000 | D33: 45721 | E33: 502LAUGH | F33: 4:40:53 pm | G33: M0BUF4311 | I33: 1 | J33: Yes | K33: 26 | L33: PS70 | M33: 13500 | P33: 45720 | R33: 4 | S33: 54000 | T33: PE | U33: 202659400 REVA0001 | V33: 0 | W33: 54000 | X33: 0 | Y33: 0 | Z33: 0 | AA33: 0 | AD33: 0 | AM33: 202659400 REVA | AN33: S19314 | AP33: 0 | AQ33: 0 | AR33: 0 | AS33: 0 | AT33: 0 | AU33: 0 | AY33: No | AZ33: W662214 | BA33: 0 | BC33: S19314 | BF33: H0064649
A34: W0680123 | B34: 10000 | C34: 10000 | D34: 45720 | E34: 502LAUGH | F34: 0.42174769 | G34: 24222F05004001003 | I34: 1 | J34: Yes | K34: 65 | L34: PMJ7 | M34: 2250 | P34: 45720 | R34: 80 | S34: 180000 | T34: PE | U34: TSMB00532010001 | V34: 0 | W34: 180000 | X34: 0 | Y34: 0 | Z34: 0 | AA34: 0 | AD34: 0 | AM34: TSMB0053201 | AN34: T20104 | AP34: 0 | AQ34: 0 | AR34: 0 | AS34: 0 | AT34: 0 | AU34: 0 | AY34: No | AZ34: W662216 | BA34: 0 | BC34: T20104 | BF34: PR006402
A35: W0680190 | B35: 10000 | C35: 20000 | D35: 45721 | E35: 502LAUGH | F35: 9:18:38 am | G35: 4103001U5 | I35: 1 | J35: Yes | K35: 94 | L35: PM09 | M35: 3000 | P35: 45720 | R35: 4 | S35: 12000 | T35: PE | U35: 0B49096 REVAA0001 | V35: 0 | W35: 12000 | X35: 0 | Y35: 0 | Z35: 0 | AA35: 0 | AD35: 0 | AM35: 0B49096 REVAA | AN35: W23041-TH | AP35: 0 | AQ35: 0 | AR35: 0 | AS35: 0 | AT35: 0 | AU35: 0 | AY35: No | AZ35: W662587 | BA35: 0 | BC35: W23041-TH | BF35: H0064660
A36: W0680247 | B36: 10000 | C36: 10000 | D36: 45722 | E36: 502LAUGH | F36: 8:42:30 am | G36: 501222196 | I36: 1 | J36: Yes | K36: 72 | L36: PMJ4 | M36: 1667 | P36: 45720 | R36: 30 | S36: 50010 | T36: PE | U36: Q.C. ACCEPTED LA0001 | V36: 0 | W36: 40000 | X36: 10010 | Y36: 0 | Z36: 0 | AA36: 0 | AD36: 0 | AM36: Q.C. ACCEPTED LABEL | AN36: S19254 | AP36: 0 | AQ36: 0 | AR36: 0 | AS36: 0 | AT36: 0 | AU36: 0 | AY36: No | AZ36: W662217 | BA36: 0 | BC36: S19254 | BF36: S0359019
A37: W0680265 | B37: 10000 | C37: 10000 | D37: 45720 | E37: 502LAUGH | F37: 5:39:52 pm | G37: SG-5622228 01 | I37: 1 | J37: Yes | K37: 59 | L37: PS74 | M37: 1000 | P37: 45720 | R37: 6 | S37: 6000 | T37: PE | U37: 15058365 REVB0001 | V37: 0 | W37: 6000 | X37: 0 | Y37: 0 | Z37: 0 | AA37: 0 | AD37: 0 | AM37: 15058365 REVB | AN37: I09180 | AP37: 0 | AQ37: 0 | AR37: 0 | AS37: 0 | AT37: 0 | AU37: 0 | AY37: No | AZ37: W662173 | BA37: 0 | BC37: I09180 | BF37: S0359037
A38: W0680265 | B38: 20000 | C38: 10000 | D38: 45720 | E38: 502LAUGH | F38: 5:39:52 pm | G38: SG-5622228 01 | I38: 1 | J38: Yes | K38: 59 | L38: PS74 | M38: 500 | P38: 45720 | R38: 6 | S38: 3000 | T38: PE | U38: 15058365 REVB0001 | V38: 0 | W38: 3000 | X38: 0 | Y38: 0 | Z38: 0 | AA38: 0 | AD38: 0 | AM38: 15058365 REVB | AN38: I09180 | AP38: 0 | AQ38: 0 | AR38: 0 | AS38: 0 | AT38: 0 | AU38: 0 | AY38: No | AZ38: W662173 | BA38: 0 | BC38: I09180 | BF38: S0359037
A39: W0680379 | B39: 10000 | C39: 10000 | D39: 45721 | E39: 502LAUGH | F39: 0.47946759 | G39: SG-5627551-01 | I39: 1 | J39: Yes | K39: 59 | L39: PS74 | M39: 5000 | P39: 45720 | R39: 6 | S39: 30000 | T39: PE | U39: 15056431 REVB0001 | V39: 0 | W39: 30000 | X39: 0 | Y39: 0 | Z39: 0 | AA39: 0 | AD39: 0 | AM39: 15056431 REVB | AN39: I09180-US | AP39: 0 | AQ39: 0 | AR39: 0 | AS39: 0 | AT39: 0 | AU39: 0 | AY39: No | AZ39: W662219 | BA39: 0 | BC39: I09180-US | BF39: S0359202
A40: W0680386 | B40: 10000 | C40: 10000 | D40: 45720 | E40: 502LAUGH | F40: 3:06:08 pm | G40: J00Q865011525 | I40: 1 | J40: Yes | K40: 71 | L40: PS95 | M40: 2500 | P40: 45720 | R40: 4 | S40: 10000 | T40: PE | U40: 83624410001 | V40: 0 | W40: 10000 | X40: 0 | Y40: 0 | Z40: 0 | AA40: 0 | AD40: 0 | AM40: 8362441 | AN40: B02083 | AP40: 0 | AQ40: 0 | AR40: 0 | AS40: 0 | AT40: 0 | AU40: 0 | AY40: No | AZ40: W662174 | BA40: 0 | BC40: B02083 | BF40: S0359207
A41: W0680390 | B41: 10000 | C41: 10000 | D41: 45720 | E41: 502LAUGH | F41: 4:40:51 pm | G41: J00K66020 | I41: 1 | J41: Yes | K41: 71 | L41: PS95 | M41: 1667 | P41: 45720 | R41: 6 | S41: 10002 | T41: PE | U41: 83634480001 | V41: 0 | W41: 10000 | X41: 2 | Y41: 0 | Z41: 0 | AA41: 0 | AD41: 0 | AM41: 8363448 | AN41: B02083 | AP41: 0 | AQ41: 0 | AR41: 0 | AS41: 0 | AT41: 0 | AU41: 0 | AY41: No | AZ41: W662175 | BA41: 0 | BC41: B02083 | BF41: S0359207
...

Sheet 5-Mar
A1: Production Output
A2: Filter: Date Completed: 05/03/25
A4: Work Order No. | B4: Work Order Line No. | C4: WO Journal Line No. | D4: Add Date | E4: Add User | F4: Add Time | G4: Material Batch No. | H4: Die Cut | I4: Process No. | J4: Posted | K4: Machine Code | L4: Staff Code | M4: No. of Press | N4: Date Started | O4: Time Started | P4: Date Completed | Q4: Time Completed | R4: No. of Ups | S4: Printed Quantity | T4: Journal Type | U4: Item Code | V4: Quantity | W4: QC Approved Quantity | X4: Rejected Quantity | Y4: Roll | Z4: Length | AA4: Width | AB4: Length UOM | AC4: Width UOM | AD4: RM Quantity | AE4: Material Code | AF4: Variant Code | AG4: Request Delivery Date | AH4: Non QC Record | AI4: Link to Line No. | AJ4: Related | AK4: Expire Date | AL4: Label Remark | AM4: Customer Part Number | AN4: Customer Code | AO4: ddmm | AP4: Label Packing Quantity 1 | AQ4: Label Quantity 1 | AR4: Label Packing Quantity 2 | AS4: Label Quantity 2 | AT4: Label Packing Quantity 3 | AU4: Label Quantity 3 | AV4: UOM for Label Printing | AW4: QC Inspector | AX4: Summarised Period | AY4: Summarised | AZ4: Posted Work Order No. | BA4: Colour | BB4: Currency | BC4: Ref Customer | BD4: Group | BE4: PO | BF4: Source Doc. No.
A5: W0675403 | B5: 10000 | C5: 40000 | D5: 45730 | E5: 502LAUGH | F5: 8:37:26 am | G5: 10639931087/10639931085/10620258096/10620258095/10620258094 | I5: 3 | J5: Yes | K5: 91 | L5: QM87 | M5: 100000 | P5: 45721 | R5: 9 | S5: 900000 | T5: PE | U5: 5180-0102-BH2120001 | V5: 0 | W5: 892857 | X5: 7143 | Y5: 0 | Z5: 0 | AA5: 0 | AD5: 0 | AM5: 5180-0102-BH212 | AN5: H08031-JIM | AP5: 0 | AQ5: 0 | AR5: 0 | AS5: 0 | AT5: 0 | AU5: 0 | AY5: No | AZ5: W662931 | BA5: 0 | BC5: H08031-JIM | BF5: S0353204
A6: W0676833 | B6: 10000 | C6: 10000 | D6: 45722 | E6: 502LAUGH | F6: 8:43:47 am | G6: 4042448203724 | I6: 1 | J6: Yes | K6: 60 | L6: PM30 | M6: 1500 | P6: 45721 | R6: 8 | S6: 12000 | T6: PE | U6: TPK-847994-00100001 | V6: 0 | W6: 20000 | X6: -8000 | Y6: 0 | Z6: 0 | AA6: 0 | AD6: 0 | AM6: TPK-847994-0010 | AN6: Z26002 | AP6: 0 | AQ6: 0 | AR6: 0 | AS6: 0 | AT6: 0 | AU6: 0 | AY6: No | AZ6: W662410 | BA6: 0 | BC6: Z26002 | BF6: S0355033
A7: W0676970 | B7: 10000 | C7: 10000 | D7: 45721 | E7: 502LAUGH | F7: 4:11:12 pm | G7: SG-5630465 | I7: 1 | J7: Yes | K7: 59 | L7: PS74 | M7: 6225 | P7: 45721 | R7: 2 | S7: 12450 | T7: PE | U7: 112887080001 | V7: 0 | W7: 12450 | X7: 0 | Y7: 0 | Z7: 0 | AA7: 0 | AD7: 0 | AM7: 11288708 | AN7: I09180-US | AP7: 0 | AQ7: 0 | AR7: 0 | AS7: 0 | AT7: 0 | AU7: 0 | AY7: No | AZ7: W662197 | BA7: 0 | BC7: I09180-US | BF7: S0355330
A8: W0676973 | B8: 10000 | C8: 10000 | D8: 45722 | E8: 502LAUGH | F8: 8:37:30 am | G8: SG-5630465 | I8: 1 | J8: Yes | K8: 59 | L8: PS74 | M8: 4150 | P8: 45721 | R8: 2 | S8: 8300 | T8: PE | U8: 112887320001 | V8: 0 | W8: 8300 | X8: 0 | Y8: 0 | Z8: 0 | AA8: 0 | AD8: 0 | AM8: 11288732 | AN8: I09180-US | AP8: 0 | AQ8: 0 | AR8: 0 | AS8: 0 | AT8: 0 | AU8: 0 | AY8: No | AZ8: W662198 | BA8: 0 | BC8: I09180-US | BF8: S0355330
A9: W0677293 | B9: 10000 | C9: 10000 | D9: 45729 | E9: 502LAUGH | F9: 8:34:20 am | G9: JOOTP98411525/J00WA6862 | I9: 1 | J9: Yes | K9: 110 | L9: PM11 | M9: 35500 | P9: 45721 | R9: 4 | S9: 142000 | T9: PE | U9: Z980 REV11.00001 | V9: 0 | W9: 142000 | X9: 0 | Y9: 0 | Z9: 0 | AA9: 0 | AD9: 0 | AM9: Z980 REV11.0 | AN9: R18131 | AP9: 0 | AQ9: 0 | AR9: 0 | AS9: 0 | AT9: 0 | AU9: 0 | AY9: No | AZ9: W662939 | BA9: 0 | BC9: R18131 | BF9: S0355673
A10: W0678764 | B10: 10000 | C10: 10000 | D10: 45722 | E10: 502LAUGH | F10: 8:43:47 am | G10: 4103023U5 | I10: 1 | J10: Yes | K10: 46 | L10: PS66 | M10: 7000 | P10: 45721 | R10: 1 | S10: 7000 | T10: PE | U10: 250-6168-000001 | V10: 0 | W10: 7000 | X10: 0 | Y10: 0 | Z10: 0 | AA10: 0 | AD10: 0 | AM10: 250-6168-00 | AN10: J10025-PHL-SG | AP10: 0 | AQ10: 0 | AR10: 0 | AS10: 0 | AT10: 0 | AU10: 0 | AY10: No | AZ10: W662417 | BA10: 0 | BC10: J10025-PHL-SG | BF10: S0357505
A11: W0678765 | B11: 10000 | C11: 10000 | D11: 45722 | E11: 502LAUGH | F11: 0.53783565 | G11: 4111520U5 | I11: 1 | J11: Yes | K11: 61 | L11: PM61 | M11: 6667 | P11: 45721 | R11: 6 | S11: 40002 | T11: PE | U11: 250-6171-000001 | V11: 0 | W11: 40000 | X11: 2 | Y11: 0 | Z11: 0 | AA11: 0 | AD11: 0 | AM11: 250-6171-00 | AN11: J10025-PHL-SG | AP11: 0 | AQ11: 0 | AR11: 0 | AS11: 0 | AT11: 0 | AU11: 0 | AY11: No | AZ11: W662418 | BA11: 0 | BC11: J10025-PHL-SG | BF11: S0357505
A12: W0678766 | B12: 10000 | C12: 10000 | D12: 45721 | E12: 502LAUGH | F12: 4:40:04 pm | G12: 4111520U5 | I12: 1 | J12: Yes | K12: 61 | L12: PM61 | M12: 6667 | P12: 45721 | R12: 6 | S12: 40002 | T12: PE | U12: 250-6172-000001 | V12: 0 | W12: 40000 | X12: 2 | Y12: 0 | Z12: 0 | AA12: 0 | AD12: 0 | AM12: 250-6172-00 | AN12: J10025-PHL-SG | AP12: 0 | AQ12: 0 | AR12: 0 | AS12: 0 | AT12: 0 | AU12: 0 | AY12: No | AZ12: W662419 | BA12: 0 | BC12: J10025-PHL-SG | BF12: S0357505
A13: W0678981 | B13: 10000 | C13: 10000 | D13: 45722 | E13: 502LAUGH | F13: 8:37:30 am | G13: SG-5630465 | I13: 1 | J13: Yes | K13: 59 | L13: PS74 | M13: 415 | P13: 45721 | R13: 2 | S13: 830 | T13: PE | U13: 112887320001 | V13: 0 | W13: 830 | X13: 0 | Y13: 0 | Z13: 0 | AA13: 0 | AD13: 0 | AM13: 11288732 | AN13: I09180 | AP13: 0 | AQ13: 0 | AR13: 0 | AS13: 0 | AT13: 0 | AU13: 0 | AY13: No | AZ13: W662202 | BA13: 0 | BC13: I09180 | BF13: S0357744
A14: W0679026 | B14: 10000 | C14: 10000 | D14: 45722 | E14: 502LAUGH | F14: 0.53451389 | G14: 4067S1 | I14: 1 | J14: Yes | K14: 78 | L14: PM84 | M14: 2000 | P14: 45721 | R14: 1 | S14: 2000 | T14: PE | U14: 1871210001 | V14: 0 | W14: 1000 | X14: 1000 | Y14: 0 | Z14: 0 | AA14: 0 | AD14: 0 | AM14: 187121 | AN14: P16186 | AP14: 0 | AQ14: 0 | AR14: 0 | AS14: 0 | AT14: 0 | AU14: 0 | AY14: No | AZ14: W662203 | BA14: 0 | BC14: P16186 | BF14: S0357788
A15: W0679026 | B15: 10000 | C15: 20000 | D15: 45722 | E15: 502LAUGH | F15: 0.53453704 | G15: 4067S1 | I15: 2 | J15: Yes | K15: 65 | L15: PMJ7 | M15: 2000 | P15: 45721 | R15: 1 | S15: 2000 | T15: PE | U15: 1871210001 | V15: 0 | W15: 1000 | X15: 1000 | Y15: 0 | Z15: 0 | AA15: 0 | AD15: 0 | AM15: 187121 | AN15: P16186 | AP15: 0 | AQ15: 0 | AR15: 0 | AS15: 0 | AT15: 0 | AU15: 0 | AY15: No | AZ15: W662203 | BA15: 0 | BC15: P16186 | BF15: S0357788
A16: W0679220 | B16: 10000 | C16: 50000 | D16: 45723 | E16: 502LAUGH | F16: 5:25:12 pm | G16: BXB022-02 | I16: 2 | J16: Yes | K16: 62 | L16: PM75 | M16: 35000 | P16: 45721 | R16: 1 | S16: 35000 | T16: PE | U16: Y00-0000928-000001 | V16: 0 | W16: 35000 | X16: 0 | Y16: 0 | Z16: 0 | AA16: 0 | AD16: 0 | AM16: 300-0000396-00 | AN16: F06170-JIANGSU | AP16: 0 | AQ16: 0 | AR16: 0 | AS16: 0 | AT16: 0 | AU16: 0 | AY16: No | AZ16: W662433 | BA16: 0 | BC16: F06170-JIANGSU | BF16: S0357841
A17: W0679251 | B17: 10000 | C17: 10000 | D17: 45721 | E17: 502LAUGH | F17: 0.45724537 | G17: M0BA89700 | I17: 1 | J17: Yes | K17: 12 | L17: PP05 | M17: 2000 | P17: 45721 | R17: 1 | S17: 2000 | T17: PE | U17: 250-0121-000001 | V17: 0 | W17: 2000 | X17: 0 | Y17: 0 | Z17: 0 | AA17: 0 | AD17: 0 | AM17: 250-0121-00 | AN17: J10025 | AP17: 0 | AQ17: 0 | AR17: 0 | AS17: 0 | AT17: 0 | AU17: 0 | AY17: No | AZ17: W662204 | BA17: 0 | BC17: J10025 | BF17: S0357887
