Workbook
Name Slicer_Customer_Name: #N/A
Name Slicer_Machine_Code: #N/A
Name Slicer_Machine_Name: #N/A
Name Slicer_Machine_Name1: #N/A
Name Slicer_Staff_Code: #N/A

Sheet 01-Apr
A1: Production Output
A2: Filter: Date Completed: 01/04/25
A4: Work Order No. | B4: Work Order Line No. | C4: WO Journal Line No. | D4: Add Date | E4: Add User | F4: Add Time | G4: Material Batch No. | H4: Die Cut | I4: Process No. | J4: Posted | K4: Machine Code | L4: Staff Code | M4: No. of Press | N4: Date Started | O4: Time Started | P4: Date Completed | Q4: Time Completed | R4: No. of Ups | S4: Printed Quantity | T4: Journal Type | U4: Item Code | V4: Quantity | W4: QC Approved Quantity | X4: Rejected Quantity | Y4: Roll | Z4: Length | AA4: Width | AB4: Length UOM | AC4: Width UOM | AD4: RM Quantity | AE4: Material Code | AF4: Variant Code | AG4: Request Delivery Date | AH4: Non QC Record | AI4: Link to Line No. | AJ4: Related | AK4: Expire Date | AL4: Label Remark | AM4: Customer Part Number | AN4: Customer Code | AO4: ddmm | AP4: Label Packing Quantity 1 | AQ4: Label Quantity 1 | AR4: Label Packing Quantity 2 | AS4: Label Quantity 2 | AT4: Label Packing Quantity 3 | AU4: Label Quantity 3 | AV4: UOM for Label Printing | AW4: QC Inspector | AX4: Summarised Period | AY4: Summarised | AZ4: Posted Work Order No. | BA4: Colour | BB4: Currency | BC4: Ref Customer | BD4: Group | BE4: PO | BF4: Source Doc. No.
A5: W0680449 | B5: 10000 | C5: 10000 | D5: 45786 | E5: 502LAUGH | F5: 9:26:40 am | G5: 2321164 | H5: DC03278 | I5: 1 | J5: No | K5: 88 | L5: PP24 | M5: 3500 | P5: 45748 | R5: 1 | S5: 3500 | T5: PE | U5: CE-1070129715-010001 | V5: 0 | W5: 0 | X5: 0 | Y5: 0 | Z5: 0 | AA5: 0 | AD5: 0 | AH5: No | AI5: 0 | AJ5: No | AM5: CE-1070129715-01 | AN5: C03043 | AP5: 0 | AQ5: 0 | AR5: 0 | AS5: 0 | AT5: 0 | AU5: 0 | AY5: No | BC5: C03043 | BF5: S0359242
A6: W0682349 | B6: 10000 | C6: 10000 | D6: 45751 | E6: 502LAUGH | F6: 5:16:20 pm | G6: 10620258022 | H6: FDC30934 | I6: 1 | J6: No | K6: 79 | L6: PM16 | M6: 200 | P6: 45748 | R6: 36 | S6: 7200 | T6: PE | U6: CZ633-800050001 | V6: 0 | W6: 0 | X6: 0 | Y6: 0 | Z6: 0 | AA6: 0 | AD6: 0 | AH6: No | AI6: 0 | AJ6: No | AM6: CZ633-80005 | AN6: H08031-JIM | AP6: 0 | AQ6: 0 | AR6: 0 | AS6: 0 | AT6: 0 | AU6: 0 | AY6: No | BC6: H08031-JIM | BF6: S0361845
A7: W0682425 | B7: 10000 | C7: 10000 | D7: 45751 | E7: 502LAUGH | F7: 5:15:26 pm | G7: 10620258022 | H7: FDC30934 | I7: 1 | J7: No | K7: 79 | L7: PM16 | M7: 167 | P7: 45748 | R7: 36 | S7: 6012 | T7: PE | U7: CZ635-800050001 | V7: 0 | W7: 0 | X7: 0 | Y7: 0 | Z7: 0 | AA7: 0 | AD7: 0 | AH7: No | AI7: 0 | AJ7: No | AM7: CZ635-80005 | AN7: H08031-JIM | AP7: 0 | AQ7: 0 | AR7: 0 | AS7: 0 | AT7: 0 | AU7: 0 | AY7: No | BC7: H08031-JIM | BF7: S0361902
A8: W0670634 | B8: 10000 | C8: 40000 | D8: 45748 | E8: 502LAUGH | F8: 5:42:25 pm | G8: D005H7770 | I8: 1 | J8: Yes | K8: 73 | L8: PM59 | M8: 3667 | P8: 45748 | R8: 30 | S8: 110010 | T8: PE | U8: R390-411 REV1.00001 | V8: 0 | W8: 104761 | X8: 5249 | Y8: 0 | Z8: 0 | AA8: 0 | AD8: 0 | AM8: R390-411 REV1.0 | AN8: R18131-MEIBAN MIC-M | AP8: 0 | AQ8: 0 | AR8: 0 | AS8: 0 | AT8: 0 | AU8: 0 | AY8: No | AZ8: W664003 | BA8: 0 | BC8: R18131-MEIBAN MIC-M | BF8: S0348898
A9: W0670634 | B9: 10000 | C9: 50000 | D9: 45748 | E9: 502LAUGH | F9: 5:42:25 pm | G9: D005H7770 | I9: 2 | J9: Yes | K9: 73 | L9: PM59 | M9: 3334 | P9: 45748 | R9: 30 | S9: 100020 | T9: PE | U9: R390-411 REV1.00001 | V9: 0 | W9: 100010 | X9: 10 | Y9: 0 | Z9: 0 | AA9: 0 | AD9: 0 | AM9: R390-411 REV1.0 | AN9: R18131-MEIBAN MIC-M | AP9: 0 | AQ9: 0 | AR9: 0 | AS9: 0 | AT9: 0 | AU9: 0 | AY9: No | AZ9: W664003 | BA9: 0 | BC9: R18131-MEIBAN MIC-M | BF9: S0348898
A10: W0675399 | B10: 10000 | C10: 30000 | D10: 45751 | E10: 502LAUGH | F10: 0.44092593 | G10: 10639931053/10639931059/10639931056/10639931055 | I10: 2 | J10: Yes | K10: 77 | L10: PM74 | M10: 29723 | P10: 45748 | R10: 36 | S10: 1070028 | T10: PE | U10: 5180-0100-BH2120001 | V10: 0 | W10: 1000000 | X10: 70028 | Y10: 0 | Z10: 0 | AA10: 0 | AD10: 0 | AM10: 5180-0100-BH212 | AN10: H08031-JIM | AP10: 0 | AQ10: 0 | AR10: 0 | AS10: 0 | AT10: 0 | AU10: 0 | AY10: No | AZ10: W664068 | BA10: 0 | BC10: H08031-JIM | BF10: S0353202
A11: W0679222 | B11: 10000 | C11: 10000 | D11: 45749 | E11: 502LAUGH | F11: 3:35:20 pm | G11: J00TP9191/J00WA7110 | I11: 1 | J11: Yes | K11: 111 | L11: PM46 | M11: 24375 | P11: 45748 | R11: 8 | S11: 195000 | T11: PE | U11: Z512 REV 6.00001 | V11: 0 | W11: 195000 | X11: 0 | Y11: 0 | Z11: 0 | AA11: 0 | AD11: 0 | AM11: Z512 REV 8.0 | AN11: R18131 | AP11: 0 | AQ11: 0 | AR11: 0 | AS11: 0 | AT11: 0 | AU11: 0 | AY11: No | AZ11: W664076 | BA11: 0 | BC11: R18131 | BF11: S0357874
A12: W0680426 | B12: 10000 | C12: 10000 | D12: 45754 | E12: 502LAUGH | F12: 9:01:59 am | G12: 1010831/80117500/XHX24911A1407/XHX2412190201/WO2024/5284 | I12: 1 | J12: Yes | K12: 103 | L12: PM47 | M12: 41875 | P12: 45748 | R12: 8 | S12: 335000 | T12: PE | U12: MT273730001 | V12: 0 | W12: 335000 | X12: 0 | Y12: 0 | Z12: 0 | AA12: 0 | AD12: 0 | AM12: MT27373 | AN12: Z26002 | AP12: 0 | AQ12: 0 | AR12: 0 | AS12: 0 | AT12: 0 | AU12: 0 | AY12: No | AZ12: W664503 | BA12: 0 | BC12: Z26002 | BF12: S0359228
A13: W0680426 | B13: 10000 | C13: 20000 | D13: 45754 | E13: 502LAUGH | F13: 9:01:59 am | G13: 1010831/80117500/XHX24911A1407/XHX2412190201/WO2024/5284 | I13: 1 | J13: Yes | K13: 103N | L13: PM41 | M13: 48125 | P13: 45748 | R13: 8 | S13: 385000 | T13: PE | U13: MT273730001 | V13: 0 | W13: 385000 | X13: 0 | Y13: 0 | Z13: 0 | AA13: 0 | AD13: 0 | AM13: MT27373 | AN13: Z26002 | AP13: 0 | AQ13: 0 | AR13: 0 | AS13: 0 | AT13: 0 | AU13: 0 | AY13: No | AZ13: W664503 | BA13: 0 | BC13: Z26002 | BF13: S0359228
A14: W0680873 | B14: 10000 | C14: 10000 | D14: 45750 | E14: 502LAUGH | F14: 0.4421875 | G14: 502200327 | I14: 1 | J14: Yes | K14: 59 | L14: PS74 | M14: 32000 | P14: 45748 | R14: 18 | S14: 576000 | T14: PE | U14: 7062430001 | V14: 0 | W14: 552000 | X14: 24000 | Y14: 0 | Z14: 0 | AA14: 0 | AD14: 0 | AM14: 706243 INDEX07 | AN14: V22000-DE | AP14: 0 | AQ14: 0 | AR14: 0 | AS14: 0 | AT14: 0 | AU14: 0 | AY14: No | AZ14: W665408 | BA14: 0 | BC14: V22000-DE | BF14: S0360724
A15: W0680948 | B15: 10000 | C15: 10000 | D15: 45749 | E15: 502LAUGH | F15: 8:32:31 am | G15: 3082510U9/4032711U5 | I15: 1 | J15: Yes | K15: 61 | L15: PM68 | M15: 500 | P15: 45748 | R15: 1 | S15: 500 | T15: PE | U15: 701684070001 | V15: 0 | W15: 500 | X15: 0 | Y15: 0 | Z15: 0 | AA15: 0 | AD15: 0 | AM15: 70168407 | AN15: P16186 | AP15: 0 | AQ15: 0 | AR15: 0 | AS15: 0 | AT15: 0 | AU15: 0 | AY15: No | AZ15: W663620 | BA15: 0 | BC15: P16186 | BF15: S0360882
A16: W0681067 | B16: 10000 | C16: 10000 | D16: 45749 | E16: 502LAUGH | F16: 8:35:58 am | G16: 4177S1/3830U7060 | I16: 1 | J16: Yes | K16: 78 | L16: PM84 | M16: 1000 | P16: 45748 | R16: 3 | S16: 3000 | T16: PE | U16: 4.4017009e+17 | V16: 0 | W16: 3000 | X16: 0 | Y16: 0 | Z16: 0 | AA16: 0 | AD16: 0 | AM16: 44017008600402 | AN16: T20096 | AP16: 0 | AQ16: 0 | AR16: 0 | AS16: 0 | AT16: 0 | AU16: 0 | AY16: No | AZ16: W663637 | BA16: 0 | BC16: T20096 | BF16: S0360941
A17: W0681280 | B17: 10000 | C17: 40000 | D17: 45749 | E17: 502LAUGH | F17: 8:35:14 am | G17: L5114U8024/405172625 | I17: 2 | J17: Yes | K17: 60 | L17: PM30 | M17: 750 | P17: 45748 | R17: 2 | S17: 1500 | T17: PE | U17: TSMC00350020001 | V17: 0 | W17: 429 | X17: 1071 | Y17: 0 | Z17: 0 | AA17: 0 | AD17: 0 | AM17: TSMC0035002 | AN17: T20104 | AP17: 0 | AQ17: 0 | AR17: 0 | AS17: 0 | AT17: 0 | AU17: 0 | AY17: No | AZ17: W663663 | BA17: 0 | BC17: T20104 | BF17: S0361067
A18: W0681379 | B18: 10000 | C18: 10000 | D18: 45748 | E18: 502LAUGH | F18: 3:51:58 pm | G18: BZA050-02 | I18: 1 | J18: Yes | K18: 46 | L18: PS66 | M18: 3000 | P18: 45748 | R18: 1 | S18: 3000 | T18: PE | U18: IMK-50001 | V18: 0 | W18: 3000 | X18: 0 | Y18: 0 | Z18: 0 | AA18: 0 | AD18: 0 | AM18: IMK-5 | AN18: G07075 | AP18: 0 | AQ18: 0 | AR18: 0 | AS18: 0 | AT18: 0 | AU18: 0 | AY18: No | AZ18: W663684 | BA18: 0 | BC18: G07075 | BF18: S0361130
A19: W0681513 | B19: 10000 | C19: 20000 | D19: 45749 | E19: 502LAUGH | F19: 8:35:14 am | G19: M0BTQ4850 | I19: 1 | J19: Yes | K19: 94 | L19: PM09 | M19: 10000 | P19: 45748 | R19: 4 | S19: 40000 | T19: PE | U19: L001-773057-00000007 | V19: 0 | W19: 40000 | X19: 0 | Y19: 0 | Z19: 0 | AA19: 0 | AD19: 0 | AM19: L001-773057-000007CM | AN19: W23041-TH | AP19: 0 | AQ19: 0 | AR19: 0 | AS19: 0 | AT19: 0 | AU19: 0 | AY19: No | AZ19: W664539 | BA19: 0 | BC19: W23041-TH | BF19: H0064786
A20: W0681514 | B20: 10000 | C20: 10000 | D20: 45749 | E20: 502LAUGH | F20: 9:46:52 am | G20: M0BTQ4850 | I20: 1 | J20: Yes | K20: 94 | L20: PM09 | M20: 10000 | P20: 45748 | R20: 4 | S20: 40000 | T20: PE | U20: L001-773057-00000007 | V20: 0 | W20: 40000 | X20: 0 | Y20: 0 | Z20: 0 | AA20: 0 | AD20: 0 | AM20: L001-773057-000007CM | AN20: W23041-TH | AP20: 0 | AQ20: 0 | AR20: 0 | AS20: 0 | AT20: 0 | AU20: 0 | AY20: No | AZ20: W664987 | BA20: 0 | BC20: W23041-TH | BF20: H0064787
A21: W0681678 | B21: 10000 | C21: 20000 | D21: 45749 | E21: 502LAUGH | F21: 0.47717593 | G21: U4A04S306 | I21: 2 | J21: Yes | K21: 60 | L21: PM30 | M21: 7000 | P21: 45748 | R21: 1 | S21: 7000 | T21: PE | U21: 60005003-D-GREEN0001 | V21: 0 | W21: 5000 | X21: 2000 | Y21: 0 | Z21: 0 | AA21: 0 | AD21: 0 | AM21: 60005003-D-GREEN | AN21: B02083 | AP21: 0 | AQ21: 0 | AR21: 0 | AS21: 0 | AT21: 0 | AU21: 0 | AY21: No | AZ21: W663754 | BA21: 0 | BC21: B02083 | BF21: S0361285
A22: W0681702 | B22: 10000 | C22: 10000 | D22: 45749 | E22: 502LAUGH | F22: 8:35:14 am | G22: M0BTQ4850 | I22: 1 | J22: Yes | K22: 94 | L22: PM09 | M22: 250 | P22: 45748 | R22: 4 | S22: 1000 | T22: PE | U22: L001-773057-00000007 | V22: 0 | W22: 1000 | X22: 0 | Y22: 0 | Z22: 0 | AA22: 0 | AD22: 0 | AM22: L001-773057-000007CM | AN22: X24001-WD-SUZHOU | AP22: 0 | AQ22: 0 | AR22: 0 | AS22: 0 | AT22: 0 | AU22: 0 | AY22: No | AZ22: W664118 | BA22: 0 | BC22: X24001-WD-SUZHOU | BF22: S0361288
A23: W0681760 | B23: 10000 | C23: 10000 | D23: 45749 | E23: 502LAUGH | F23: 8:58:47 am | G23: E0223920 | I23: 1 | J23: Yes | K23: 63 | L23: PM80 | M23: 2500 | P23: 45748 | R23: 72 | S23: 180000 | T23: PE | U23: 1114-790-00007 R0001 | V23: 0 | W23: 180000 | X23: 0 | Y23: 0 | Z23: 0 | AA23: 0 | AD23: 0 | AM23: 1114-790-00007 REVD | AN23: M13337-SMD | AP23: 0 | AQ23: 0 | AR23: 0 | AS23: 0 | AT23: 0 | AU23: 0 | AY23: No | AZ23: W664119 | BA23: 0 | BC23: M13337-SMD | BF23: S0361340
A24: W0681763 | B24: 10000 | C24: 10000 | D24: 45749 | E24: 502LAUGH | F24: 8:58:47 am | G24: 1006323 | I24: 1 | J24: Yes | K24: 63 | L24: PM80 | M24: 3334 | P24: 45748 | R24: 90 | S24: 300060 | T24: PE | U24: 1115-790-00003 R0001 | V24: 0 | W24: 300000 | X24: 60 | Y24: 0 | Z24: 0 | AA24: 0 | AD24: 0 | AM24: 1115-790-00003 REVB | AN24: M13337-SMD | AP24: 0 | AQ24: 0 | AR24: 0 | AS24: 0 | AT24: 0 | AU24: 0 | AY24: No | AZ24: W663771 | BA24: 0 | BC24: M13337-SMD | BF24: S0361340
A25: W0681773 | B25: 10000 | C25: 10000 | D25: 45748 | E25: 502LAUGH | F25: 5:43:19 pm | G25: D005H7770 | I25: 1 | J25: Yes | K25: 73 | L25: PM59 | M25: 667 | P25: 45748 | R25: 30 | S25: 20010 | T25: PE | U25: R390-411 REV1.00001 | V25: 0 | W25: 14334 | X25: 5676 | Y25: 0 | Z25: 0 | AA25: 0 | AD25: 0 | AM25: R390-411 REV1.0 | AN25: R18131-MEIBAN MIC-M | AP25: 0 | AQ25: 0 | AR25: 0 | AS25: 0 | AT25: 0 | AU25: 0 | AY25: No | AZ25: W664121 | BA25: 0 | BC25: R18131-MEIBAN MIC-M | BF25: GRR62158
A26: W0681773 | B26: 10000 | C26: 20000 | D26: 45748 | E26: 502LAUGH | F26: 5:43:19 pm | G26: D005H7770 | I26: 2 | J26: Yes | K26: 73 | L26: PM59 | M26: 478 | P26: 45748 | R26: 30 | S26: 14340 | T26: PE | U26: R390-411 REV1.00001 | V26: 0 | W26: 14334 | X26: 6 | Y26: 0 | Z26: 0 | AA26: 0 | AD26: 0 | AM26: R390-411 REV1.0 | AN26: R18131-MEIBAN MIC-M | AP26: 0 | AQ26: 0 | AR26: 0 | AS26: 0 | AT26: 0 | AU26: 0 | AY26: No | AZ26: W664121 | BA26: 0 | BC26: R18131-MEIBAN MIC-M | BF26: GRR62158
A27: W0681890 | B27: 10000 | C27: 10000 | D27: 45748 | E27: 502LAUGH | F27: 5:40:42 pm | G27: 3082510U9/4032711U5 | I27: 1 | J27: Yes | K27: 61 | L27: PM68 | M27: 3500 | P27: 45748 | R27: 1 | S27: 3500 | T27: PE | U27: 701684140001 | V27: 0 | W27: 3500 | X27: 0 | Y27: 0 | Z27: 0 | AA27: 0 | AD27: 0 | AM27: 70168414 | AN27: P16186 | AP27: 0 | AQ27: 0 | AR27: 0 | AS27: 0 | AT27: 0 | AU27: 0 | AY27: No | AZ27: W663811 | BA27: 0 | BC27: P16186 | BF27: S0361400
A28: W0681984 | B28: 10000 | C28: 10000 | D28: 45749 | E28: 502LAUGH | F28: 8:55:00 am | G28: E0223920 | I28: 1 | J28: Yes | K28: 63 | L28: PM80 | M28: 4667 | P28: 45748 | R28: 90 | S28: 420030 | T28: PE | U28: 1115-790-00001 R0001 | V28: 0 | W28: 420000 | X28: 30 | Y28: 0 | Z28: 0 | AA28: 0 | AD28: 0 | AM28: 1115-790-00001 REVB | AN28: M13337-SMD | AP28: 0 | AQ28: 0 | AR28: 0 | AS28: 0 | AT28: 0 | AU28: 0 | AY28: No | AZ28: W663819 | BA28: 0 | BC28: M13337-SMD | BF28: S0361340
A29: W0682107 | B29: 10000 | C29: 10000 | D29: 45754 | E29: 502LAUGH | F29: 8:56:52 am | G29: M0BUQ9711/M0BUF4241 | I29: 1 | J29: Yes | K29: 70 | L29: PS84 | M29: 60000 | P29: 45748 | R29: 2 | S29: 120000 | T29: PE | U29: 725427400 REVA0002 | V29: 0 | W29: 120000 | X29: 0 | Y29: 0 | Z29: 0 | AA29: 0 | AD29: 0 | AM29: 725427400 REVA | AN29: S19081-TH | AP29: 0 | AQ29: 0 | AR29: 0 | AS29: 0 | AT29: 0 | AU29: 0 | AY29: No | AZ29: W664144 | BA29: 0 | BC29: S19081-TH | BF29: H0064875
A30: W0682197 | B30: 10000 | C30: 20000 | D30: 45749 | E30: 502LAUGH | F30: 8:40:57 am | G30: U4A04S213/3082512U9 | I30: 2 | J30: Yes | K30: 100 | L30: PM87 | M30: 600 | P30: 45748 | R30: 1 | S30: 600 | T30: PE | U30: 104489220001 | V30: 0 | W30: 500 | X30: 100 | Y30: 0 | Z30: 0 | AA30: 0 | AD30: 0 | AM30: 10448922 | AN30: I09109 | AP30: 0 | AQ30: 0 | AR30: 0 | AS30: 0 | AT30: 0 | AU30: 0 | AY30: No | AZ30: W663883 | BA30: 0 | BC30: I09109 | BF30: S0361694
A31: W0682199 | B31: 10000 | C31: 20000 | D31: 45749 | E31: 502LAUGH | F31: 8:40:57 am | G31: U4A04S213/3082512U9 | I31: 2 | J31: Yes | K31: 100 | L31: PM87 | M31: 20 | P31: 45748 | R31: 1 | S31: 20 | T31: PE | U31: 104489220001 | V31: 0 | W31: 20 | X31: 0 | Y31: 0 | Z31: 0 | AA31: 0 | AD31: 0 | AM31: 10448922 | AN31: I09109 | AP31: 0 | AQ31: 0 | AR31: 0 | AS31: 0 | AT31: 0 | AU31: 0 | AY31: No | AZ31: W663885 | BA31: 0 | BC31: I09109 | BF31: ZSA101777
A32: W0682202 | B32: 10000 | C32: 10000 | D32: 45748 | E32: 502LAUGH | F32: 2:53:33 pm | G32: 4092S1 | I32: 1 | J32: Yes | K32: 61 | L32: PM68 | M32: 100 | P32: 45748 | R32: 1 | S32: 100 | T32: PE | U32: 03225846-010001 | V32: 0 | W32: 100 | X32: 0 | Y32: 0 | Z32: 0 | AA32: 0 | AD32: 0 | AM32: 03225846-01 | AN32: A01413 | AP32: 0 | AQ32: 0 | AR32: 0 | AS32: 0 | AT32: 0 | AU32: 0 | AY32: No | AZ32: W664151 | BA32: 0 | BC32: A01413 | BF32: S0361696
A33: W0682213 | B33: 10000 | C33: 20000 | D33: 45749 | E33: 502LAUGH | F33: 8:44:50 am | G33: 3082512U9/U4A04S213 | I33: 2 | J33: Yes | K33: 100 | L33: PM87 | M33: 600 | P33: 45748 | R33: 1 | S33: 600 | T33: PE | U33: 107355880001 | V33: 0 | W33: 500 | X33: 100 | Y33: 0 | Z33: 0 | AA33: 0 | AD33: 0 | AM33: 10735588 | AN33: I09109 | AP33: 0 | AQ33: 0 | AR33: 0 | AS33: 0 | AT33: 0 | AU33: 0 | AY33: No | AZ33: W663891 | BA33: 0 | BC33: I09109 | BF33: S0361705
A34: W0682214 | B34: 10000 | C34: 20000 | D34: 45749 | E34: 502LAUGH | F34: 8:49:04 am | G34: 3082512U9/U4A04S213 | I34: 2 | J34: Yes | K34: 100 | L34: PM87 | M34: 600 | P34: 45748 | R34: 1 | S34: 600 | T34: PE | U34: 107355890001 | V34: 0 | W34: 500 | X34: 100 | Y34: 0 | Z34: 0 | AA34: 0 | AD34: 0 | AM34: 10735589 | AN34: I09109 | AP34: 0 | AQ34: 0 | AR34: 0 | AS34: 0 | AT34: 0 | AU34: 0 | AY34: No | AZ34: W663892 | BA34: 0 | BC34: I09109 | BF34: S0361705
A35: W0682215 | B35: 10000 | C35: 20000 | D35: 45749 | E35: 502LAUGH | F35: 8:42:50 am | G35: D105Y48501525 | I35: 2 | J35: Yes | K35: 92 | L35: PM87 | M35: 600 | P35: 45748 | R35: 1 | S35: 600 | T35: PE | U35: 107472350001 | V35: 0 | W35: 500 | X35: 100 | Y35: 0 | Z35: 0 | AA35: 0 | AD35: 0 | AM35: 10747235 | AN35: I09109 | AP35: 0 | AQ35: 0 | AR35: 0 | AS35: 0 | AT35: 0 | AU35: 0 | AY35: No | AZ35: W663893 | BA35: 0 | BC35: I09109 | BF35: S0361705
A36: W0682217 | B36: 10000 | C36: 20000 | D36: 45749 | E36: 502LAUGH | F36: 8:44:50 am | G36: 3082512U9/U4A04S213 | I36: 2 | J36: Yes | K36: 100 | L36: PM87 | M36: 20 | P36: 45748 | R36: 1 | S36: 20 | T36: PE | U36: 107355880001 | V36: 0 | W36: 20 | X36: 0 | Y36: 0 | Z36: 0 | AA36: 0 | AD36: 0 | AM36: 10735588 | AN36: I09109 | AP36: 0 | AQ36: 0 | AR36: 0 | AS36: 0 | AT36: 0 | AU36: 0 | AY36: No | AZ36: W663895 | BA36: 0 | BC36: I09109 | BF36: ZSA101778
A37: W0682218 | B37: 10000 | C37: 20000 | D37: 45749 | E37: 502LAUGH | F37: 8:49:04 am | G37: 3082512U9/U4A04S213 | I37: 2 | J37: Yes | K37: 100 | L37: PM87 | M37: 20 | P37: 45748 | R37: 1 | S37: 20 | T37: PE | U37: 107355890001 | V37: 0 | W37: 20 | X37: 0 | Y37: 0 | Z37: 0 | AA37: 0 | AD37: 0 | AM37: 10735589 | AN37: I09109 | AP37: 0 | AQ37: 0 | AR37: 0 | AS37: 0 | AT37: 0 | AU37: 0 | AY37: No | AZ37: W663896 | BA37: 0 | BC37: I09109 | BF37: ZSA101778
A38: W0682219 | B38: 10000 | C38: 20000 | D38: 45749 | E38: 502LAUGH | F38: 8:42:50 am | G38: D105Y48501525 | I38: 2 | J38: Yes | K38: 92 | L38: PM87 | M38: 20 | P38: 45748 | R38: 1 | S38: 20 | T38: PE | U38: 107472350001 | V38: 0 | W38: 20 | X38: 0 | Y38: 0 | Z38: 0 | AA38: 0 | AD38: 0 | AM38: 10747235 | AN38: I09109 | AP38: 0 | AQ38: 0 | AR38: 0 | AS38: 0 | AT38: 0 | AU38: 0 | AY38: No | AZ38: W663897 | BA38: 0 | BC38: I09109 | BF38: ZSA101778
A39: W0682274 | B39: 10000 | C39: 20000 | D39: 45748 | E39: 502LAUGH | F39: 5:44:23 pm | G39: M0BVE5230 | I39: 2 | J39: Yes | K39: 73 | L39: PM59 | M39: 250 | P39: 45748 | R39: 1 | S39: 250 | T39: PE | U39: 10056878001 REVA0001 | V39: 0 | W39: 250 | X39: 0 | Y39: 0 | Z39: 0 | AA39: 0 | AD39: 0 | AM39: 10056878001 REVA | AN39: E05166-JAPAC | AP39: 0 | AQ39: 0 | AR39: 0 | AS39: 0 | AT39: 0 | AU39: 0 | AY39: No | AZ39: W664156 | BA39: 0 | BC39: E05166-JAPAC | BF39: S0361738
A40: W0682283 | B40: 10000 | C40: 20000 | D40: 45749 | E40: 502LAUGH | F40: 0.4762963 | G40: J00ML98601525 | I40: 2 | J40: Yes | K40: 92 | L40: PM87 | M40: 600 | P40: 45748 | R40: 1 | S40: 600 | T40: PE | U40: 107343730001 | V40: 0 | W40: 500 | X40: 100 | Y40: 0 | Z40: 0 | AA40: 0 | AD40: 0 | AM40: 10734373 | AN40: I09109 | AP40: 0 | AQ40: 0 | AR40: 0 | AS40: 0 | AT40: 0 | AU40: 0 | AY40: No | AZ40: W663922 | BA40: 0 | BC40: I09109 | BF40: S0361740
A41: W0682284 | B41: 10000 | C41: 20000 | D41: 45749 | E41: 502LAUGH | F41: 0.47821759 | G41: J00ML98601525 | I41: 2 | J41: Yes | K41: 92 | L41: PM87 | M41: 600 | P41: 45748 | R41: 1 | S41: 600 | T41: PE | U41: 107343750001 | V41: 0 | W41: 500 | X41: 100 | Y41: 0 | Z41: 0 | AA41: 0 | AD41: 0 | AM41: 10734375 | AN41: I09109 | AP41: 0 | AQ41: 0 | AR41: 0 | AS41: 0 | AT41: 0 | AU41: 0 | AY41: No | AZ41: W663923 | BA41: 0 | BC41: I09109 | BF41: S0361740
...

Sheet 02-Apr
A1: Production Output
A2: Filter: Date Completed: 02/04/25
A4: Work Order No. | B4: Work Order Line No. | C4: WO Journal Line No. | D4: Add Date | E4: Add User | F4: Add Time | G4: Material Batch No. | H4: Die Cut | I4: Process No. | J4: Posted | K4: Machine Code | L4: Staff Code | M4: No. of Press | N4: Date Started | O4: Time Started | P4: Date Completed | Q4: Time Completed | R4: No. of Ups | S4: Printed Quantity | T4: Journal Type | U4: Item Code | V4: Quantity | W4: QC Approved Quantity | X4: Rejected Quantity | Y4: Roll | Z4: Length | AA4: Width | AB4: Length UOM | AC4: Width UOM | AD4: RM Quantity | AE4: Material Code | AF4: Variant Code | AG4: Request Delivery Date | AH4: Non QC Record | AI4: Link to Line No. | AJ4: Related | AK4: Expire Date | AL4: Label Remark | AM4: Customer Part Number | AN4: Customer Code | AO4: ddmm | AP4: Label Packing Quantity 1 | AQ4: Label Quantity 1 | AR4: Label Packing Quantity 2 | AS4: Label Quantity 2 | AT4: Label Packing Quantity 3 | AU4: Label Quantity 3 | AV4: UOM for Label Printing | AW4: QC Inspector | AX4: Summarised Period | AY4: Summarised | AZ4: Posted Work Order No. | BA4: Colour | BB4: Currency | BC4: Ref Customer | BD4: Group | BE4: PO | BF4: Source Doc. No.
A5: W0675399 | B5: 10000 | C5: 40000 | D5: 45751 | E5: 502LAUGH | F5: 0.44092593 | G5: 10639931053/10639931059/10639931056/10639931055 | I5: 3 | J5: Yes | K5: 91 | L5: QM54 | M5: 112000 | P5: 45749 | R5: 9 | S5: 1008000 | T5: PE | U5: 5180-0100-BH2120001 | V5: 0 | W5: 1000000 | X5: 8000 | Y5: 0 | Z5: 0 | AA5: 0 | AD5: 0 | AM5: 5180-0100-BH212 | AN5: H08031-JIM | AP5: 0 | AQ5: 0 | AR5: 0 | AS5: 0 | AT5: 0 | AU5: 0 | AY5: No | AZ5: W664068 | BA5: 0 | BC5: H08031-JIM | BF5: S0353202
A6: W0676859 | B6: 10000 | C6: 20000 | D6: 45758 | E6: 502LAUGH | F6: 0.46591435 | G6: BZC064-08 | I6: 1 | J6: Yes | K6: 79 | L6: PM16 | M6: 8700 | P6: 45749 | R6: 5 | S6: 43500 | T6: PE | U6: RR 6X6-WHITE0001 | V6: 0 | W6: 40910 | X6: 2590 | Y6: 0 | Z6: 0 | AA6: 0 | AD6: 0 | AM6: RR 6X6-WHITE | AN6: E05203 | AP6: 0 | AQ6: 0 | AR6: 0 | AS6: 0 | AT6: 0 | AU6: 0 | AY6: No | AZ6: W664979 | BA6: 0 | BC6: E05203 | BF6: S0355056
A7: W0677858 | B7: 10000 | C7: 10000 | D7: 45776 | E7: 502LAUGH | F7: 8:28:44 am | G7: BVG027-04/BWK014-01 | I7: 1 | J7: Yes | K7: 88 | L7: PP24 | M7: 3500 | P7: 45749 | R7: 1 | S7: 3500 | T7: PE | U7: CE6401-9000-00080001 | V7: 0 | W7: 1500 | X7: 2000 | Y7: 0 | Z7: 0 | AA7: 0 | AD7: 0 | AM7: CE6401-9000-0008 | AN7: C03043 | AP7: 0 | AQ7: 0 | AR7: 0 | AS7: 0 | AT7: 0 | AU7: 0 | AY7: No | AZ7: W665665 | BA7: 0 | BC7: C03043 | BF7: S0356636
A8: W0678504 | B8: 10000 | C8: 20000 | D8: 45755 | E8: 502LAUGH | F8: 8:51:28 am | G8: J00WA6960/J00TB1180/J00VB8021/J00TB1740 | I8: 1 | J8: Yes | K8: 110 | L8: PM40 | M8: 126000 | P8: 45749 | R8: 4 | S8: 504000 | T8: PE | U8: Z980 REV11.00001 | V8: 0 | W8: 504000 | X8: 0 | Y8: 0 | Z8: 0 | AA8: 0 | AD8: 0 | AM8: Z980 REV11.0 | AN8: R18131 | AP8: 0 | AQ8: 0 | AR8: 0 | AS8: 0 | AT8: 0 | AU8: 0 | AY8: No | AZ8: W664487 | BA8: 0 | BC8: R18131 | BF8: S0357206
A9: W0678953 | B9: 10000 | C9: 10000 | D9: 45750 | E9: 502LAUGH | F9: 8:35:03 am | G9: J206L2871 | I9: 1 | J9: Yes | K9: 65 | L9: PMJ7 | M9: 9000 | P9: 45749 | R9: 6 | S9: 54000 | T9: PE | U9: Z513 REV3.00001 | V9: 0 | W9: 54000 | X9: 0 | Y9: 0 | Z9: 0 | AA9: 0 | AD9: 0 | AM9: Z513 REV3.0 | AN9: R18131 | AP9: 0 | AQ9: 0 | AR9: 0 | AS9: 0 | AT9: 0 | AU9: 0 | AY9: No | AZ9: W664073 | BA9: 0 | BC9: R18131 | BF9: S0357731
A10: W0679222 | B10: 10000 | C10: 20000 | D10: 45749 | E10: 502LAUGH | F10: 3:42:07 pm | G10: J00TP9191/J00WA7110 | I10: 1 | J10: Yes | K10: 111 | L10: PM11 | M10: 5625 | P10: 45749 | R10: 8 | S10: 45000 | T10: PE | U10: Z512 REV 6.00001 | V10: 0 | W10: 45000 | X10: 0 | Y10: 0 | Z10: 0 | AA10: 0 | AD10: 0 | AM10: Z512 REV 8.0 | AN10: R18131 | AP10: 0 | AQ10: 0 | AR10: 0 | AS10: 0 | AT10: 0 | AU10: 0 | AY10: No | AZ10: W664076 | BA10: 0 | BC10: R18131 | BF10: S0357874
A11: W0680522 | B11: 10000 | C11: 10000 | D11: 45749 | E11: 502LAUGH | F11: 5:41:53 pm | G11: 2101110U5/3082510U9 | I11: 1 | J11: Yes | K11: 61 | L11: PM68 | M11: 1000 | P11: 45749 | R11: 4 | S11: 4000 | T11: PE | U11: 726017 REV4000001 | V11: 0 | W11: 4000 | X11: 0 | Y11: 0 | Z11: 0 | AA11: 0 | AD11: 0 | AM11: 726017 REV400 | AN11: V22000 | AP11: 0 | AQ11: 0 | AR11: 0 | AS11: 0 | AT11: 0 | AU11: 0 | AY11: No | AZ11: W664079 | BA11: 0 | BC11: V22000 | BF11: S0359313
A12: W0680734 | B12: 10000 | C12: 10000 | D12: 45750 | E12: 502LAUGH | F12: 0.42329861 | G12: TOA1G75701525 | I12: 1 | J12: Yes | K12: 82 | L12: PM11 | M12: 15000 | P12: 45749 | R12: 2 | S12: 30000 | T12: PE | U12: BL-4X60006 | V12: 0 | W12: 30000 | X12: 0 | Y12: 0 | Z12: 0 | AA12: 0 | AD12: 0 | AM12: BL-4X6 | AN12: Z26000 | AP12: 0 | AQ12: 0 | AR12: 0 | AS12: 0 | AT12: 0 | AU12: 0 | AY12: No | AZ12: W664080 | BA12: 0 | BC12: Z26000 | BF12: ZSA101751
A13: W0680747 | B13: 10000 | C13: 10000 | D13: 45749 | E13: 502LAUGH | F13: 3:37:00 pm | G13: SG-5644655 01 | I13: 1 | J13: Yes | K13: 46 | L13: PS66 | M13: 258 | P13: 45749 | R13: 4 | S13: 1032 | T13: PE | U13: 112887410001 | V13: 0 | W13: 1030 | X13: 2 | Y13: 0 | Z13: 0 | AA13: 0 | AD13: 0 | AM13: 11288741 | AN13: I09180 | AP13: 0 | AQ13: 0 | AR13: 0 | AS13: 0 | AT13: 0 | AU13: 0 | AY13: No | AZ13: W664081 | BA13: 0 | BC13: I09180 | BF13: S0359863
A14: W0680753 | B14: 10000 | C14: 10000 | D14: 45749 | E14: 502LAUGH | F14: 0.47282407 | G14: SG-5644655 01 | I14: 1 | J14: Yes | K14: 46 | L14: PS66 | M14: 258 | P14: 45749 | R14: 4 | S14: 1032 | T14: PE | U14: 112887590001 | V14: 0 | W14: 1030 | X14: 2 | Y14: 0 | Z14: 0 | AA14: 0 | AD14: 0 | AM14: 11288759 | AN14: I09180 | AP14: 0 | AQ14: 0 | AR14: 0 | AS14: 0 | AT14: 0 | AU14: 0 | AY14: No | AZ14: W663609 | BA14: 0 | BC14: I09180 | BF14: S0359866
A15: W0680754 | B15: 10000 | C15: 10000 | D15: 45749 | E15: 502LAUGH | F15: 0.47282407 | G15: SG-5644655 01 | I15: 1 | J15: Yes | K15: 46 | L15: PS66 | M15: 258 | P15: 45749 | R15: 4 | S15: 1032 | T15: PE | U15: 112887590001 | V15: 0 | W15: 1030 | X15: 2 | Y15: 0 | Z15: 0 | AA15: 0 | AD15: 0 | AM15: 11288759 | AN15: I09180 | AP15: 0 | AQ15: 0 | AR15: 0 | AS15: 0 | AT15: 0 | AU15: 0 | AY15: No | AZ15: W663610 | BA15: 0 | BC15: I09180 | BF15: S0359867
A16: W0680762 | B16: 10000 | C16: 10000 | D16: 45749 | E16: 502LAUGH | F16: 5:29:41 pm | G16: SG-5644655 01 | I16: 1 | J16: Yes | K16: 46 | L16: PS66 | M16: 258 | P16: 45749 | R16: 4 | S16: 1032 | T16: PE | U16: 112887830001 | V16: 0 | W16: 1030 | X16: 2 | Y16: 0 | Z16: 0 | AA16: 0 | AD16: 0 | AM16: 11288783 | AN16: I09180 | AP16: 0 | AQ16: 0 | AR16: 0 | AS16: 0 | AT16: 0 | AU16: 0 | AY16: No | AZ16: W664082 | BA16: 0 | BC16: I09180 | BF16: S0359875
A17: W0681211 | B17: 10000 | C17: 10000 | D17: 45751 | E17: 502LAUGH | F17: 8:35:18 am | G17: M0BUF4292/M0BUQ9711 | I17: 1 | J17: Yes | K17: 29 | L17: PS70 | M17: 24000 | P17: 45749 | R17: 2 | S17: 48000 | T17: PE | U17: 100823881-75367 0001 | V17: 0 | W17: 48000 | X17: 0 | Y17: 0 | Z17: 0 | AA17: 0 | AD17: 0 | AM17: 100823881-75367 A | AN17: S19081-TH | AP17: 0 | AQ17: 0 | AR17: 0 | AS17: 0 | AT17: 0 | AU17: 0 | AY17: No | AZ17: W664091 | BA17: 0 | BC17: S19081-TH | BF17: H0064754
A18: W0681471 | B18: 10000 | C18: 10000 | D18: 45754 | E18: 502LAUGH | F18: 8:43:38 am | G18: 4101908U5A | I18: 1 | J18: Yes | K18: 12 | L18: PP05 | M18: 42000 | P18: 45749 | R18: 1 | S18: 42000 | T18: PE | U18: 250-6223-000001 | V18: 0 | W18: 42000 | X18: 0 | Y18: 0 | Z18: 0 | AA18: 0 | AD18: 0 | AM18: 250-6223-00 | AN18: J10025 | AP18: 0 | AQ18: 0 | AR18: 0 | AS18: 0 | AT18: 0 | AU18: 0 | AY18: No | AZ18: W664533 | BA18: 0 | BC18: J10025 | BF18: S0361174
A19: W0681510 | B19: 10000 | C19: 30000 | D19: 45749 | E19: 502LAUGH | F19: 1:56:09 pm | G19: M0BSO3780 | I19: 1 | J19: Yes | K19: 94 | L19: PM94 | M19: 5000 | P19: 45749 | R19: 4 | S19: 20000 | T19: PE | U19: L001-773057-00000005 | V19: 0 | W19: 20000 | X19: 0 | Y19: 0 | Z19: 0 | AA19: 0 | AD19: 0 | AM19: L001-773057-000005CM | AN19: W23041-TH | AP19: 0 | AQ19: 0 | AR19: 0 | AS19: 0 | AT19: 0 | AU19: 0 | AY19: No | AZ19: W664538 | BA19: 0 | BC19: W23041-TH | BF19: H0064783
A20: W0681511 | B20: 10000 | C20: 20000 | D20: 45749 | E20: 502LAUGH | F20: 5:41:53 pm | G20: M0BTQ4850 | I20: 1 | J20: Yes | K20: 94 | L20: PM09 | M20: 5000 | P20: 45749 | R20: 4 | S20: 20000 | T20: PE | U20: L001-773057-00000005 | V20: 0 | W20: 20000 | X20: 0 | Y20: 0 | Z20: 0 | AA20: 0 | AD20: 0 | AM20: L001-773057-000005CM | AN20: W23041-TH | AP20: 0 | AQ20: 0 | AR20: 0 | AS20: 0 | AT20: 0 | AU20: 0 | AY20: No | AZ20: W664103 | BA20: 0 | BC20: W23041-TH | BF20: H0064784
A21: W0681576 | B21: 10000 | C21: 20000 | D21: 45751 | E21: 502LAUGH | F21: 1:46:58 pm | G21: 10620258046 | I21: 2 | J21: Yes | K21: 77 | L21: PM74 | M21: 1285 | P21: 45749 | R21: 88 | S21: 113080 | T21: PE | U21: T6N02-80020-FT0001 | V21: 0 | W21: 100000 | X21: 13080 | Y21: 0 | Z21: 0 | AA21: 0 | AD21: 0 | AM21: T6N02-80020-FT | AN21: H08031-JIM-M | AP21: 0 | AQ21: 0 | AR21: 0 | AS21: 0 | AT21: 0 | AU21: 0 | AY21: No | AZ21: W664109 | BA21: 0 | BC21: H08031-JIM-M | BF21: S0361213
A22: W0681676 | B22: 10000 | C22: 30000 | D22: 45750 | E22: 502LAUGH | F22: 8:36:27 am | G22: U4A04S306 | I22: 2 | J22: Yes | K22: 60 | L22: PM61 | M22: 3900 | P22: 45749 | R22: 1 | S22: 3900 | T22: PE | U22: 60005003-D-BLUE0001 | V22: 0 | W22: 2000 | X22: 1900 | Y22: 0 | Z22: 0 | AA22: 0 | AD22: 0 | AM22: 60005003-D-BLUE | AN22: B02083 | AP22: 0 | AQ22: 0 | AR22: 0 | AS22: 0 | AT22: 0 | AU22: 0 | AY22: No | AZ22: W663753 | BA22: 0 | BC22: B02083 | BF22: S0361285
A23: W0681677 | B23: 10000 | C23: 20000 | D23: 45750 | E23: 502LAUGH | F23: 5:04:42 pm | G23: U4A04S306 | I23: 2 | J23: Yes | K23: 60 | L23: PM30 | M23: 18000 | P23: 45749 | R23: 1 | S23: 18000 | T23: PE | U23: 60005003-D-DARK 0001 | V23: 0 | W23: 15000 | X23: 3000 | Y23: 0 | Z23: 0 | AA23: 0 | AD23: 0 | AM23: 60005003-D-DARK GREY | AN23: B02083 | AP23: 0 | AQ23: 0 | AR23: 0 | AS23: 0 | AT23: 0 | AU23: 0 | AY23: No | AZ23: W664114 | BA23: 0 | BC23: B02083 | BF23: S0361285
A24: W0681680 | B24: 10000 | C24: 20000 | D24: 45749 | E24: 502LAUGH | F24: 3:35:20 pm | G24: U4A04S306 | I24: 2 | J24: Yes | K24: 60 | L24: PM30 | M24: 2000 | P24: 45749 | R24: 1 | S24: 2000 | T24: PE | U24: 60005003-D-ROSE0001 | V24: 0 | W24: 1000 | X24: 1000 | Y24: 0 | Z24: 0 | AA24: 0 | AD24: 0 | AM24: 60005003-D-ROSE | AN24: B02083 | AP24: 0 | AQ24: 0 | AR24: 0 | AS24: 0 | AT24: 0 | AU24: 0 | AY24: No | AZ24: W663755 | BA24: 0 | BC24: B02083 | BF24: S0361285
A25: W0681681 | B25: 10000 | C25: 20000 | D25: 45749 | E25: 502LAUGH | F25: 4:17:10 pm | G25: U4A04S306 | I25: 2 | J25: Yes | K25: 60 | L25: PM61 | M25: 4000 | P25: 45749 | R25: 1 | S25: 4000 | T25: PE | U25: 60005003-D-WHITE0001 | V25: 0 | W25: 2000 | X25: 2000 | Y25: 0 | Z25: 0 | AA25: 0 | AD25: 0 | AM25: 60005003-D-WHITE | AN25: B02083 | AP25: 0 | AQ25: 0 | AR25: 0 | AS25: 0 | AT25: 0 | AU25: 0 | AY25: No | AZ25: W663756 | BA25: 0 | BC25: B02083 | BF25: S0361285
A26: W0681800 | B26: 10000 | C26: 10000 | D26: 45750 | E26: 502LAUGH | F26: 8:41:24 am | G26: E04LE7190 | I26: 1 | J26: Yes | K26: 22 | L26: PS13 | M26: 1000 | P26: 45749 | R26: 1 | S26: 1000 | T26: PE | U26: 12000 SQ FEET0001 | V26: 0 | W26: 1000 | X26: 0 | Y26: 0 | Z26: 0 | AA26: 0 | AD26: 0 | AM26: 12000 SQ FEET | AN26: T20326 | AP26: 0 | AQ26: 0 | AR26: 0 | AS26: 0 | AT26: 0 | AU26: 0 | AY26: No | AZ26: W664122 | BA26: 0 | BC26: T20326 | BF26: S0361365
A27: W0681801 | B27: 10000 | C27: 10000 | D27: 45749 | E27: 502LAUGH | F27: 5:11:48 pm | G27: E04LE7190 | I27: 1 | J27: Yes | K27: 22 | L27: PS13 | M27: 1000 | P27: 45749 | R27: 1 | S27: 1000 | T27: PE | U27: 16000 SQ FEET0001 | V27: 0 | W27: 1000 | X27: 0 | Y27: 0 | Z27: 0 | AA27: 0 | AD27: 0 | AM27: 16000 SQ FEET | AN27: T20326 | AP27: 0 | AQ27: 0 | AR27: 0 | AS27: 0 | AT27: 0 | AU27: 0 | AY27: No | AZ27: W664123 | BA27: 0 | BC27: T20326 | BF27: S0361365
A28: W0681802 | B28: 10000 | C28: 10000 | D28: 45750 | E28: 502LAUGH | F28: 8:41:24 am | G28: E04LE7190 | I28: 1 | J28: Yes | K28: 22 | L28: PS13 | M28: 2000 | P28: 45749 | R28: 1 | S28: 2000 | T28: PE | U28: 500 SQ FEET0001 | V28: 0 | W28: 2000 | X28: 0 | Y28: 0 | Z28: 0 | AA28: 0 | AD28: 0 | AM28: 500 SQ FEET | AN28: T20326 | AP28: 0 | AQ28: 0 | AR28: 0 | AS28: 0 | AT28: 0 | AU28: 0 | AY28: No | AZ28: W664124 | BA28: 0 | BC28: T20326 | BF28: S0361365
A29: W0681815 | B29: 10000 | C29: 10000 | D29: 45749 | E29: 502LAUGH | F29: 2:37:21 pm | G29: 4110602U5A | I29: 1 | J29: Yes | K29: 22 | L29: PS13 | M29: 7000 | P29: 45749 | R29: 1 | S29: 7000 | T29: PE | U29: 250-6224-000001 | V29: 0 | W29: 7000 | X29: 0 | Y29: 0 | Z29: 0 | AA29: 0 | AD29: 0 | AM29: 250-6224-00 | AN29: J10025 | AP29: 0 | AQ29: 0 | AR29: 0 | AS29: 0 | AT29: 0 | AU29: 0 | AY29: No | AZ29: W664126 | BA29: 0 | BC29: J10025 | BF29: S0361373
A30: W0681881 | B30: 10000 | C30: 10000 | D30: 45750 | E30: 502LAUGH | F30: 0.42506944 | G30: L5305U8039 | I30: 1 | J30: Yes | K30: 78 | L30: PM84 | M30: 6000 | P30: 45749 | R30: 1 | S30: 6000 | T30: PE | U30: SCREAMER LB-80X10001 | V30: 0 | W30: 6000 | X30: 0 | Y30: 0 | Z30: 0 | AA30: 0 | AD30: 0 | AM30: SCREAMER LB-80X134MM | AN30: I09146 | AP30: 0 | AQ30: 0 | AR30: 0 | AS30: 0 | AT30: 0 | AU30: 0 | AY30: No | AZ30: W664132 | BA30: 0 | BC30: I09146 | BF30: S0361394
A31: W0681895 | B31: 10000 | C31: 20000 | D31: 45754 | E31: 502LAUGH | F31: 8:47:11 am | G31: 10620258046 | I31: 2 | J31: Yes | K31: 77 | L31: PM74 | M31: 1285 | P31: 45749 | R31: 88 | S31: 113080 | T31: PE | U31: 3UB27-800030001 | V31: 0 | W31: 100000 | X31: 13080 | Y31: 0 | Z31: 0 | AA31: 0 | AD31: 0 | AM31: 3UB27-80003 | AN31: H08031-JIM-M | AP31: 0 | AQ31: 0 | AR31: 0 | AS31: 0 | AT31: 0 | AU31: 0 | AY31: No | AZ31: W664576 | BA31: 0 | BC31: H08031-JIM-M | BF31: S0361404
A32: W0681896 | B32: 10000 | C32: 20000 | D32: 45754 | E32: 502LAUGH | F32: 8:36:19 am | G32: 10620258046 | I32: 2 | J32: Yes | K32: 77 | L32: PM74 | M32: 1285 | P32: 45749 | R32: 88 | S32: 113080 | T32: PE | U32: 3YM83-800010001 | V32: 0 | W32: 100000 | X32: 13080 | Y32: 0 | Z32: 0 | AA32: 0 | AD32: 0 | AM32: 3YM83-80001 | AN32: H08031-JIM-M | AP32: 0 | AQ32: 0 | AR32: 0 | AS32: 0 | AT32: 0 | AU32: 0 | AY32: No | AZ32: W664577 | BA32: 0 | BC32: H08031-JIM-M | BF32: S0361405
A33: W0681902 | B33: 10000 | C33: 20000 | D33: 45754 | E33: 502LAUGH | F33: 5:26:27 pm | G33: 10656256096 | I33: 2 | J33: Yes | K33: 77 | L33: PM74 | M33: 1285 | P33: 45749 | R33: 88 | S33: 113080 | T33: PE | U33: 3YM75-80011-FT0001 | V33: 0 | W33: 100000 | X33: 13080 | Y33: 0 | Z33: 0 | AA33: 0 | AD33: 0 | AM33: 3YM75-80011-FT | AN33: H08031-JIM-M | AP33: 0 | AQ33: 0 | AR33: 0 | AS33: 0 | AT33: 0 | AU33: 0 | AY33: No | AZ33: W664579 | BA33: 0 | BC33: H08031-JIM-M | BF33: S0361409
A34: W0681903 | B34: 10000 | C34: 20000 | D34: 45754 | E34: 502LAUGH | F34: 3:42:29 pm | G34: 10620258039 | I34: 2 | J34: Yes | K34: 77 | L34: PM74 | M34: 2884 | P34: 45749 | R34: 77 | S34: 222068 | T34: PE | U34: 7FP20-80002-FT0001 | V34: 0 | W34: 200000 | X34: 22068 | Y34: 0 | Z34: 0 | AA34: 0 | AD34: 0 | AM34: 7FP20-80002-FT | AN34: H08031-JIM-M | AP34: 0 | AQ34: 0 | AR34: 0 | AS34: 0 | AT34: 0 | AU34: 0 | AY34: No | AZ34: W664580 | BA34: 0 | BC34: H08031-JIM-M | BF34: S0361410
A35: W0681930 | B35: 10000 | C35: 10000 | D35: 45749 | E35: 502LAUGH | F35: 0.47378472 | G35: MDRLR4W211124 | I35: 1 | J35: Yes | K35: 65 | L35: PMJ7 | M35: 112 | P35: 45749 | R35: 90 | S35: 10080 | T35: PE | U35: 720502 REV4010001 | V35: 0 | W35: 10000 | X35: 80 | Y35: 0 | Z35: 0 | AA35: 0 | AD35: 0 | AM35: 720502 REV402 | AN35: V22000 | AP35: 0 | AQ35: 0 | AR35: 0 | AS35: 0 | AT35: 0 | AU35: 0 | AY35: No | AZ35: W663818 | BA35: 0 | BC35: V22000 | BF35: S0361418
A36: W0681951 | B36: 10000 | C36: 10000 | D36: 45749 | E36: 502LAUGH | F36: 2:37:21 pm | G36: 4170S1 | I36: 1 | J36: Yes | K36: 78 | L36: PM84 | M36: 3500 | P36: 45749 | R36: 1 | S36: 3500 | T36: PE | U36: 805512 REV4000001 | V36: 0 | W36: 3500 | X36: 0 | Y36: 0 | Z36: 0 | AA36: 0 | AD36: 0 | AM36: 805512 REV400 | AN36: V22000 | AP36: 0 | AQ36: 0 | AR36: 0 | AS36: 0 | AT36: 0 | AU36: 0 | AY36: No | AZ36: W664137 | BA36: 0 | BC36: V22000 | BF36: S0361431
A37: W0682027 | B37: 10000 | C37: 10000 | D37: 45750 | E37: 502LAUGH | F37: 5:39:51 pm | G37: TW1116349-04 | I37: 1 | J37: Yes | K37: 72 | L37: PMJ4 | M37: 1459 | P37: 45749 | R37: 24 | S37: 35016 | T37: PE | U37: P1S0455 60001 | V37: 0 | W37: 30000 | X37: 5016 | Y37: 0 | Z37: 0 | AA37: 0 | AD37: 0 | AM37: P1S0455 6 | AN37: H08220 | AP37: 0 | AQ37: 0 | AR37: 0 | AS37: 0 | AT37: 0 | AU37: 0 | AY37: No | AZ37: W664139 | BA37: 0 | BC37: H08220 | BF37: S0361538
A38: W0682041 | B38: 10000 | C38: 20000 | D38: 45754 | E38: 502LAUGH | F38: 8:50:45 am | G38: 10620258046 | I38: 2 | J38: Yes | K38: 77 | L38: PM74 | M38: 1285 | P38: 45749 | R38: 88 | S38: 113080 | T38: PE | U38: T6M58-800040001 | V38: 0 | W38: 100000 | X38: 13080 | Y38: 0 | Z38: 0 | AA38: 0 | AD38: 0 | AM38: T6M58-80004 | AN38: H08031-JIM-M | AP38: 0 | AQ38: 0 | AR38: 0 | AS38: 0 | AT38: 0 | AU38: 0 | AY38: No | AZ38: W664591 | BA38: 0 | BC38: H08031-JIM-M | BF38: S0361539
A39: W0682071 | B39: 10000 | C39: 20000 | D39: 45750 | E39: 502LAUGH | F39: 8:39:28 am | G39: 3082510U9/401180925 | I39: 2 | J39: Yes | K39: 100 | L39: PM87 | M39: 700 | P39: 45749 | R39: 1 | S39: 700 | T39: PE | U39: 107176710001 | V39: 0 | W39: 500 | X39: 200 | Y39: 0 | Z39: 0 | AA39: 0 | AD39: 0 | AM39: 10717671 | AN39: I09109 | AP39: 0 | AQ39: 0 | AR39: 0 | AS39: 0 | AT39: 0 | AU39: 0 | AY39: No | AZ39: W663861 | BA39: 0 | BC39: I09109 | BF39: S0361542
A40: W0682088 | B40: 10000 | C40: 10000 | D40: 45751 | E40: 502LAUGH | F40: 2:29:24 pm | G40: 501060725 | I40: 1 | J40: Yes | K40: 31 | L40: PS19 | M40: 5000 | P40: 45749 | R40: 1 | S40: 5000 | T40: PE | U40: OHARA LABEL0001 | V40: 0 | W40: 5000 | X40: 0 | Y40: 0 | Z40: 0 | AA40: 0 | AD40: 0 | AM40: OHARA LABEL | AN40: H08217 | AP40: 0 | AQ40: 0 | AR40: 0 | AS40: 0 | AT40: 0 | AU40: 0 | AY40: No | AZ40: W664142 | BA40: 0 | BC40: H08217 | BF40: S0361562
A41: W0682114 | B41: 10000 | C41: 20000 | D41: 45754 | E41: 502LAUGH | F41: 2:46:49 pm | G41: 10656256096 | I41: 2 | J41: Yes | K41: 77 | L41: PM74 | M41: 853 | P41: 45749 | R41: 88 | S41: 75064 | T41: PE | U41: 3YM56-80009-FT0001 | V41: 0 | W41: 60000 | X41: 15064 | Y41: 0 | Z41: 0 | AA41: 0 | AD41: 0 | AM41: 3YM56-80009-FT | AN41: H08031-JIM-M | AP41: 0 | AQ41: 0 | AR41: 0 | AS41: 0 | AT41: 0 | AU41: 0 | AY41: No | AZ41: W664602 | BA41: 0 | BC41: H08031-JIM-M | BF41: S0361568
...

Sheet 03-Apr
A1: Production Output
A2: Filter: Date Completed: 03/04/25
A4: Work Order No. | B4: Work Order Line No. | C4: WO Journal Line No. | D4: Add Date | E4: Add User | F4: Add Time | G4: Material Batch No. | H4: Die Cut | I4: Process No. | J4: Posted | K4: Machine Code | L4: Staff Code | M4: No. of Press | N4: Date Started | O4: Time Started | P4: Date Completed | Q4: Time Completed | R4: No. of Ups | S4: Printed Quantity | T4: Journal Type | U4: Item Code | V4: Quantity | W4: QC Approved Quantity | X4: Rejected Quantity | Y4: Roll | Z4: Length | AA4: Width | AB4: Length UOM | AC4: Width UOM | AD4: RM Quantity | AE4: Material Code | AF4: Variant Code | AG4: Request Delivery Date | AH4: Non QC Record | AI4: Link to Line No. | AJ4: Related | AK4: Expire Date | AL4: Label Remark | AM4: Customer Part Number | AN4: Customer Code | AO4: ddmm | AP4: Label Packing Quantity 1 | AQ4: Label Quantity 1 | AR4: Label Packing Quantity 2 | AS4: Label Quantity 2 | AT4: Label Packing Quantity 3 | AU4: Label Quantity 3 | AV4: UOM for Label Printing | AW4: QC Inspector | AX4: Summarised Period | AY4: Summarised | AZ4: Posted Work Order No. | BA4: Colour | BB4: Currency | BC4: Ref Customer | BD4: Group | BE4: PO | BF4: Source Doc. No.
A5: W0678968 | B5: 10000 | C5: 40000 | D5: 45751 | E5: 502LAUGH | F5: 2:54:08 pm | G5: M0BJQ96701065/M0BTQ4840 | H5: FSC30254 | I5: 1 | J5: No | K5: 94 | L5: PM09 | M5: 10000 | P5: 45750 | R5: 4 | S5: 40000 | T5: PE | U5: L001-773057-00000006 | V5: 0 | W5: 0 | X5: 0 | Y5: 0 | Z5: 0 | AA5: 0 | AD5: 0 | AH5: No | AI5: 0 | AJ5: No | AM5: L001-773057-000006CM | AN5: W23041-TH | AP5: 0 | AQ5: 0 | AR5: 0 | AS5: 0 | AT5: 0 | AU5: 0 | AY5: No | BC5: W23041-TH | BF5: H0064486
A6: W0672069 | B6: 10000 | C6: 10000 | D6: 45761 | E6: 502LAUGH | F6: 9:00:06 am | G6: 4072413U5 | I6: 1 | J6: Yes | K6: 82 | L6: PM11 | M6: 100000 | P6: 45750 | R6: 1 | S6: 100000 | T6: PE | U6: 48X110MM TRANS L0001 | V6: 0 | W6: 100000 | X6: 0 | Y6: 0 | Z6: 0 | AA6: 0 | AD6: 0 | AM6: 48X110MM TRANS LBL | AN6: Z26000 | AP6: 0 | AQ6: 0 | AR6: 0 | AS6: 0 | AT6: 0 | AU6: 0 | AY6: No | AZ6: W664977 | BA6: 0 | BC6: Z26000 | BF6: ZSA101609
A7: W0676859 | B7: 10000 | C7: 30000 | D7: 45758 | E7: 502LAUGH | F7: 0.46591435 | G7: BZC064-08 | I7: 1 | J7: Yes | K7: 93N | L7: PC02 | M7: 14334 | P7: 45750 | R7: 6 | S7: 86004 | T7: PE | U7: RR 6X6-WHITE0001 | V7: 0 | W7: 80884 | X7: 5120 | Y7: 0 | Z7: 0 | AA7: 0 | AD7: 0 | AM7: RR 6X6-WHITE | AN7: E05203 | AP7: 0 | AQ7: 0 | AR7: 0 | AS7: 0 | AT7: 0 | AU7: 0 | AY7: No | AZ7: W664979 | BA7: 0 | BC7: E05203 | BF7: S0355056
A8: W0676859 | B8: 10000 | C8: 50000 | D8: 45758 | E8: 502LAUGH | F8: 0.46591435 | G8: BZC064-08 | I8: 2 | J8: Yes | K8: 76 | L8: PM46 | M8: 97000 | P8: 45750 | R8: 2 | S8: 194000 | T8: PE | U8: RR 6X6-WHITE0001 | V8: 0 | W8: 205500 | X8: -11500 | Y8: 0 | Z8: 0 | AA8: 0 | AD8: 0 | AM8: RR 6X6-WHITE | AN8: E05203 | AP8: 0 | AQ8: 0 | AR8: 0 | AS8: 0 | AT8: 0 | AU8: 0 | AY8: No | AZ8: W664979 | BA8: 0 | BC8: E05203 | BF8: S0355056
A9: W0679518 | B9: 10000 | C9: 10000 | D9: 45754 | E9: 505KANGHS | F9: 8:43:15 am | G9: J00VB8021 | I9: 1 | J9: Yes | K9: 102 | L9: PM61 | M9: 27000 | P9: 45750 | R9: 2 | S9: 54000 | T9: PE | U9: R001-410200001 | V9: 0 | W9: 54000 | X9: 0 | Y9: 0 | Z9: 0 | AA9: 0 | AD9: 0 | AM9: R001-41020 | AN9: R18131 | AP9: 0 | AQ9: 0 | AR9: 0 | AS9: 0 | AT9: 0 | AU9: 0 | AY9: No | AZ9: W664493 | BA9: 0 | BC9: R18131 | BF9: S0358294
A10: W0679624 | B10: 10000 | C10: 20000 | D10: 45755 | E10: 502LAUGH | F10: 8:53:34 am | G10: E04OB9810 | I10: 2 | J10: Yes | K10: 62 | L10: PMJ0 | M10: 35000 | P10: 45750 | R10: 1 | S10: 35000 | T10: PE | U10: Y00-0000928-000001 | V10: 0 | W10: 35000 | X10: 0 | Y10: 0 | Z10: 0 | AA10: 0 | AD10: 0 | AM10: 300-0000396-00 | AN10: F06170-JIANGSU | AP10: 0 | AQ10: 0 | AR10: 0 | AS10: 0 | AT10: 0 | AU10: 0 | AY10: No | AZ10: W664495 | BA10: 0 | BC10: F06170-JIANGSU | BF10: S0358339
A11: W0680991 | B11: 10000 | C11: 20000 | D11: 45751 | E11: 502LAUGH | F11: 0.44171296 | G11: M0BRZ2270990 | I11: 1 | J11: Yes | K11: 78 | L11: PM84 | M11: 12500 | P11: 45750 | R11: 4 | S11: 50000 | T11: PE | U11: 5180-38640001 | V11: 0 | W11: 50000 | X11: 0 | Y11: 0 | Z11: 0 | AA11: 0 | AD11: 0 | AM11: 5180-3864 | AN11: H08031-JIM | AP11: 0 | AQ11: 0 | AR11: 0 | AS11: 0 | AT11: 0 | AU11: 0 | AY11: No | AZ11: W664086 | BA11: 0 | BC11: H08031-JIM | BF11: S0360900
A12: W0681128 | B12: 10000 | C12: 10000 | D12: 45751 | E12: 502LAUGH | F12: 8:39:49 am | G12: 4067S1 | I12: 1 | J12: Yes | K12: 22 | L12: PS13 | M12: 1000 | P12: 45750 | R12: 1 | S12: 1000 | T12: PE | U12: 806778 REV4010001 | V12: 0 | W12: 1000 | X12: 0 | Y12: 0 | Z12: 0 | AA12: 0 | AD12: 0 | AM12: 806778 REV401 | AN12: V22000 | AP12: 0 | AQ12: 0 | AR12: 0 | AS12: 0 | AT12: 0 | AU12: 0 | AY12: No | AZ12: W664519 | BA12: 0 | BC12: V22000 | BF12: S0361013
A13: W0681350 | B13: 10000 | C13: 10000 | D13: 45751 | E13: 502LAUGH | F13: 8:36:19 am | G13: SG-5644655 01 | I13: 1 | J13: Yes | K13: 59 | L13: PS74 | M13: 5000 | P13: 45750 | R13: 6 | S13: 30000 | T13: PE | U13: 15058371 REVB0001 | V13: 0 | W13: 30000 | X13: 0 | Y13: 0 | Z13: 0 | AA13: 0 | AD13: 0 | AM13: 15058371 REVB | AN13: I09180 | AP13: 0 | AQ13: 0 | AR13: 0 | AS13: 0 | AT13: 0 | AU13: 0 | AY13: No | AZ13: W664093 | BA13: 0 | BC13: I09180 | BF13: S0361100
A14: W0681351 | B14: 10000 | C14: 10000 | D14: 45751 | E14: 502LAUGH | F14: 8:36:19 am | G14: SG-5644655 01 | I14: 1 | J14: Yes | K14: 59 | L14: PS74 | M14: 5000 | P14: 45750 | R14: 6 | S14: 30000 | T14: PE | U14: 15058371 REVB0001 | V14: 0 | W14: 30000 | X14: 0 | Y14: 0 | Z14: 0 | AA14: 0 | AD14: 0 | AM14: 15058371 REVB | AN14: I09180 | AP14: 0 | AQ14: 0 | AR14: 0 | AS14: 0 | AT14: 0 | AU14: 0 | AY14: No | AZ14: W664094 | BA14: 0 | BC14: I09180 | BF14: S0361101
A15: W0681512 | B15: 10000 | C15: 10000 | D15: 45750 | E15: 502LAUGH | F15: 0.42506944 | G15: N0BTQ4850 | I15: 1 | J15: Yes | K15: 94 | L15: PM09 | M15: 5000 | P15: 45750 | R15: 4 | S15: 20000 | T15: PE | U15: L001-773057-00000005 | V15: 0 | W15: 20000 | X15: 0 | Y15: 0 | Z15: 0 | AA15: 0 | AD15: 0 | AM15: L001-773057-000005CM | AN15: W23041-TH | AP15: 0 | AQ15: 0 | AR15: 0 | AS15: 0 | AT15: 0 | AU15: 0 | AY15: No | AZ15: W664104 | BA15: 0 | BC15: W23041-TH | BF15: H0064785
A16: W0681636 | B16: 10000 | C16: 20000 | D16: 45750 | E16: 502LAUGH | F16: 0.46141204 | G16: SG-5644655 01 | I16: 1 | J16: Yes | K16: 59 | L16: PS74 | M16: 1000 | P16: 45750 | R16: 6 | S16: 6000 | T16: PE | U16: 15058366 REVB0001 | V16: 0 | W16: 6000 | X16: 0 | Y16: 0 | Z16: 0 | AA16: 0 | AD16: 0 | AM16: 15058366 REVB | AN16: I09180 | AP16: 0 | AQ16: 0 | AR16: 0 | AS16: 0 | AT16: 0 | AU16: 0 | AY16: No | AZ16: W664111 | BA16: 0 | BC16: I09180 | BF16: S0361256
A17: W0681637 | B17: 10000 | C17: 10000 | D17: 45750 | E17: 502LAUGH | F17: 0.46141204 | G17: SG-5644655 01 | I17: 1 | J17: Yes | K17: 59 | L17: PS74 | M17: 1000 | P17: 45750 | R17: 6 | S17: 6000 | T17: PE | U17: 15058366 REVB0001 | V17: 0 | W17: 6000 | X17: 0 | Y17: 0 | Z17: 0 | AA17: 0 | AD17: 0 | AM17: 15058366 REVB | AN17: I09180 | AP17: 0 | AQ17: 0 | AR17: 0 | AS17: 0 | AT17: 0 | AU17: 0 | AY17: No | AZ17: W664112 | BA17: 0 | BC17: I09180 | BF17: S0361257
A18: W0681637 | B18: 20000 | C18: 10000 | D18: 45750 | E18: 502LAUGH | F18: 0.46141204 | G18: SG-5644655 01 | I18: 1 | J18: Yes | K18: 59 | L18: PS74 | M18: 1000 | P18: 45750 | R18: 6 | S18: 6000 | T18: PE | U18: 15058366 REVB0001 | V18: 0 | W18: 6000 | X18: 0 | Y18: 0 | Z18: 0 | AA18: 0 | AD18: 0 | AM18: 15058366 REVB | AN18: I09180 | AP18: 0 | AQ18: 0 | AR18: 0 | AS18: 0 | AT18: 0 | AU18: 0 | AY18: No | AZ18: W664112 | BA18: 0 | BC18: I09180 | BF18: S0361257
A19: W0681675 | B19: 10000 | C19: 30000 | D19: 45751 | E19: 502LAUGH | F19: 8:34:07 am | G19: U4A04S306 | I19: 2 | J19: Yes | K19: 60 | L19: PM30 | M19: 4000 | P19: 45750 | R19: 1 | S19: 4000 | T19: PE | U19: 60005003-D LIGHT0001 | V19: 0 | W19: 2000 | X19: 2000 | Y19: 0 | Z19: 0 | AA19: 0 | AD19: 0 | AM19: 60005003-D LIGHT GRN | AN19: B02083 | AP19: 0 | AQ19: 0 | AR19: 0 | AS19: 0 | AT19: 0 | AU19: 0 | AY19: No | AZ19: W664113 | BA19: 0 | BC19: B02083 | BF19: S0361285
A20: W0681679 | B20: 10000 | C20: 20000 | D20: 45751 | E20: 502LAUGH | F20: 8:33:27 am | G20: U4A04S306 | I20: 2 | J20: Yes | K20: 60 | L20: PM30 | M20: 4900 | P20: 45750 | R20: 1 | S20: 4900 | T20: PE | U20: 60005003-D-IVORY0001 | V20: 0 | W20: 3000 | X20: 1900 | Y20: 0 | Z20: 0 | AA20: 0 | AD20: 0 | AM20: 60005003-D-IVORY | AN20: B02083 | AP20: 0 | AQ20: 0 | AR20: 0 | AS20: 0 | AT20: 0 | AU20: 0 | AY20: No | AZ20: W664115 | BA20: 0 | BC20: B02083 | BF20: S0361285
A21: W0681682 | B21: 10000 | C21: 20000 | D21: 45751 | E21: 502LAUGH | F21: 8:35:18 am | G21: U4A04S306 | I21: 2 | J21: Yes | K21: 60 | L21: PM30 | M21: 3900 | P21: 45750 | R21: 1 | S21: 3900 | T21: PE | U21: 60005003-D-YELLO0001 | V21: 0 | W21: 2000 | X21: 1900 | Y21: 0 | Z21: 0 | AA21: 0 | AD21: 0 | AM21: 60005003-D-YELLOW | AN21: B02083 | AP21: 0 | AQ21: 0 | AR21: 0 | AS21: 0 | AT21: 0 | AU21: 0 | AY21: No | AZ21: W664116 | BA21: 0 | BC21: B02083 | BF21: S0361285
A22: W0681740 | B22: 10000 | C22: 10000 | D22: 45754 | E22: 505KANGHS | F22: 8:51:41 am | G22: SG-5650696 | I22: 1 | J22: Yes | K22: 73N | L22: PM18 | M22: 18000 | P22: 45750 | R22: 12 | S22: 216000 | T22: PE | U22: 80256230001 | V22: 0 | W22: 216000 | X22: 0 | Y22: 0 | Z22: 0 | AA22: 0 | AD22: 0 | AM22: 8025623 | AN22: B02083 | AP22: 0 | AQ22: 0 | AR22: 0 | AS22: 0 | AT22: 0 | AU22: 0 | AY22: No | AZ22: W664562 | BA22: 0 | BC22: B02083 | BF22: S0361322
A23: W0681897 | B23: 10000 | C23: 20000 | D23: 45754 | E23: 502LAUGH | F23: 8:35:07 am | G23: 10620258037 | I23: 2 | J23: Yes | K23: 77 | L23: PM74 | M23: 1410 | P23: 45750 | R23: 66 | S23: 93060 | T23: PE | U23: E5Z02-80008-FT0001 | V23: 0 | W23: 80000 | X23: 13060 | Y23: 0 | Z23: 0 | AA23: 0 | AD23: 0 | AM23: E5Z02-80008-FT | AN23: H08031-JIM-M | AP23: 0 | AQ23: 0 | AR23: 0 | AS23: 0 | AT23: 0 | AU23: 0 | AY23: No | AZ23: W664578 | BA23: 0 | BC23: H08031-JIM-M | BF23: S0361406
A24: W0681907 | B24: 10000 | C24: 50000 | D24: 45751 | E24: 502LAUGH | F24: 5:33:58 pm | G24: 10620258042/10620258038 | I24: 2 | J24: Yes | K24: 77 | L24: PM74 | M24: 2728 | P24: 45750 | R24: 66 | S24: 180048 | T24: PE | U24: 3JB26-800010001 | V24: 0 | W24: 99320 | X24: 80728 | Y24: 0 | Z24: 0 | AA24: 0 | AD24: 0 | AM24: 3JB26-80001 | AN24: H08031-JIM-M | AP24: 0 | AQ24: 0 | AR24: 0 | AS24: 0 | AT24: 0 | AU24: 0 | AY24: No | AZ24: W664582 | BA24: 0 | BC24: H08031-JIM-M | BF24: S0361414
A25: W0681925 | B25: 10000 | C25: 20000 | D25: 45750 | E25: 502LAUGH | F25: 2:59:57 pm | G25: M0BTQ4840 | I25: 1 | J25: Yes | K25: 94 | L25: PM09 | M25: 5000 | P25: 45750 | R25: 4 | S25: 20000 | T25: PE | U25: L001-773057-00000005 | V25: 0 | W25: 20000 | X25: 0 | Y25: 0 | Z25: 0 | AA25: 0 | AD25: 0 | AM25: L001-773057-000005CM | AN25: W23041-TH | AP25: 0 | AQ25: 0 | AR25: 0 | AS25: 0 | AT25: 0 | AU25: 0 | AY25: No | AZ25: W664584 | BA25: 0 | BC25: W23041-TH | BF25: H0064817
A26: W0682027 | B26: 10000 | C26: 20000 | D26: 45750 | E26: 502LAUGH | F26: 5:39:51 pm | G26: TW1116349-04 | I26: 2 | J26: Yes | K26: 86 | L26: PS96 | M26: 2500 | P26: 45750 | R26: 12 | S26: 30000 | T26: PE | U26: P1S0455 60001 | V26: 0 | W26: 30000 | X26: 0 | Y26: 0 | Z26: 0 | AA26: 0 | AD26: 0 | AM26: P1S0455 6 | AN26: H08220 | AP26: 0 | AQ26: 0 | AR26: 0 | AS26: 0 | AT26: 0 | AU26: 0 | AY26: No | AZ26: W664139 | BA26: 0 | BC26: H08220 | BF26: S0361538
A27: W0682067 | B27: 10000 | C27: 10000 | D27: 45751 | E27: 502LAUGH | F27: 8:39:49 am | G27: A431833/BYG115-01/XHX2412242227 | I27: 1 | J27: Yes | K27: 60 | L27: PM30 | M27: 50 | P27: 45750 | R27: 5 | S27: 250 | T27: PE | U27: TPK-884595-00100001 | V27: 0 | W27: 250 | X27: 0 | Y27: 0 | Z27: 0 | AA27: 0 | AD27: 0 | AM27: TPK-884595-0010 | AN27: Z26002 | AP27: 0 | AQ27: 0 | AR27: 0 | AS27: 0 | AT27: 0 | AU27: 0 | AY27: No | AZ27: W664140 | BA27: 0 | BC27: Z26002 | BF27: ZSA101775
A28: W0682068 | B28: 10000 | C28: 10000 | D28: 45751 | E28: 502LAUGH | F28: 8:39:49 am | G28: A431833/BYG115-01/XHX2412242227 | I28: 1 | J28: Yes | K28: 60 | L28: PM30 | M28: 50 | P28: 45750 | R28: 5 | S28: 250 | T28: PE | U28: TPK-884596-00100001 | V28: 0 | W28: 250 | X28: 0 | Y28: 0 | Z28: 0 | AA28: 0 | AD28: 0 | AM28: TPK-884596-0010 | AN28: Z26002 | AP28: 0 | AQ28: 0 | AR28: 0 | AS28: 0 | AT28: 0 | AU28: 0 | AY28: No | AZ28: W664141 | BA28: 0 | BC28: Z26002 | BF28: ZSA101775
A29: W0682092 | B29: 10000 | C29: 10000 | D29: 45754 | E29: 505KANGHS | F29: 1:51:38 pm | G29: M0BUG7190/M0BUQ9671 | I29: 1 | J29: Yes | K29: 29 | L29: PS70 | M29: 24000 | P29: 45750 | R29: 2 | S29: 48000 | T29: PE | U29: 100823881-75367 0001 | V29: 0 | W29: 48000 | X29: 0 | Y29: 0 | Z29: 0 | AA29: 0 | AD29: 0 | AM29: 100823881-75367 A | AN29: S19081-TH | AP29: 0 | AQ29: 0 | AR29: 0 | AS29: 0 | AT29: 0 | AU29: 0 | AY29: No | AZ29: W664593 | BA29: 0 | BC29: S19081-TH | BF29: H0064860
A30: W0682108 | B30: 10000 | C30: 10000 | D30: 45756 | E30: 502LAUGH | F30: 0.44246528 | G30: M0BUQ9711/M0BUQ9671/M0BUG7190/M0BUF4292 | I30: 1 | J30: Yes | K30: 70 | L30: PS84 | M30: 60000 | P30: 45750 | R30: 2 | S30: 120000 | T30: PE | U30: 725427400 REVA0002 | V30: 0 | W30: 120000 | X30: 0 | Y30: 0 | Z30: 0 | AA30: 0 | AD30: 0 | AM30: 725427400 REVA | AN30: S19081-TH | AP30: 0 | AQ30: 0 | AR30: 0 | AS30: 0 | AT30: 0 | AU30: 0 | AY30: No | AZ30: W664600 | BA30: 0 | BC30: S19081-TH | BF30: H0064876
A31: W0682170 | B31: 10000 | C31: 20000 | D31: 45750 | E31: 502LAUGH | F31: 1:46:38 pm | G31: SG-5644655 01 | I31: 1 | J31: Yes | K31: 59 | L31: PS74 | M31: 1000 | P31: 45750 | R31: 6 | S31: 6000 | T31: PE | U31: 15058360-3K-R8LT0001 | V31: 0 | W31: 6000 | X31: 0 | Y31: 0 | Z31: 0 | AA31: 0 | AD31: 0 | AM31: 15058360-3K-R8LT-28 | AN31: I09180 | AP31: 0 | AQ31: 0 | AR31: 0 | AS31: 0 | AT31: 0 | AU31: 0 | AY31: No | AZ31: W664146 | BA31: 0 | BC31: I09180 | BF31: S0361671
A32: W0682170 | B32: 20000 | C32: 10000 | D32: 45750 | E32: 502LAUGH | F32: 1:46:38 pm | G32: SG-5644655 01 | I32: 1 | J32: Yes | K32: 59 | L32: PS74 | M32: 1000 | P32: 45750 | R32: 6 | S32: 6000 | T32: PE | U32: 15058360-3K-R8LT0001 | V32: 0 | W32: 6000 | X32: 0 | Y32: 0 | Z32: 0 | AA32: 0 | AD32: 0 | AM32: 15058360-3K-R8LT-28 | AN32: I09180 | AP32: 0 | AQ32: 0 | AR32: 0 | AS32: 0 | AT32: 0 | AU32: 0 | AY32: No | AZ32: W664146 | BA32: 0 | BC32: I09180 | BF32: S0361671
A33: W0682174 | B33: 10000 | C33: 10000 | D33: 45751 | E33: 502LAUGH | F33: 8:36:19 am | G33: SG-5644655 01 | I33: 1 | J33: Yes | K33: 59 | L33: PS74 | M33: 5000 | P33: 45750 | R33: 6 | S33: 30000 | T33: PE | U33: 15058371 REVB0001 | V33: 0 | W33: 30000 | X33: 0 | Y33: 0 | Z33: 0 | AA33: 0 | AD33: 0 | AM33: 15058371 REVB | AN33: I09180 | AP33: 0 | AQ33: 0 | AR33: 0 | AS33: 0 | AT33: 0 | AU33: 0 | AY33: No | AZ33: W664147 | BA33: 0 | BC33: I09180 | BF33: S0361675
A34: W0682224 | B34: 10000 | C34: 20000 | D34: 45751 | E34: 502LAUGH | F34: 3:41:29 pm | G34: TW1116349-04 | I34: 2 | J34: Yes | K34: 86 | L34: PS96 | M34: 7000 | P34: 45750 | R34: 12 | S34: 84000 | T34: PE | U34: P1S0455 60001 | V34: 0 | W34: 84000 | X34: 0 | Y34: 0 | Z34: 0 | AA34: 0 | AD34: 0 | AM34: P1S0455 6 | AN34: H08220 | AP34: 0 | AQ34: 0 | AR34: 0 | AS34: 0 | AT34: 0 | AU34: 0 | AY34: No | AZ34: W664153 | BA34: 0 | BC34: H08220 | BF34: S0361708
A35: W0682241 | B35: 10000 | C35: 10000 | D35: 45751 | E35: 502LAUGH | F35: 4:17:10 pm | G35: J00WT7100 | I35: 1 | J35: Yes | K35: 72 | L35: PM17 | M35: 2500 | P35: 45750 | R35: 6 | S35: 15000 | T35: PE | U35: 80834720001 | V35: 0 | W35: 10000 | X35: 5000 | Y35: 0 | Z35: 0 | AA35: 0 | AD35: 0 | AM35: 8083472 | AN35: B02083 | AP35: 0 | AQ35: 0 | AR35: 0 | AS35: 0 | AT35: 0 | AU35: 0 | AY35: No | AZ35: W664619 | BA35: 0 | BC35: B02083 | BF35: S0361716
A36: W0682242 | B36: 10000 | C36: 10000 | D36: 45756 | E36: 502LAUGH | F36: 8:34:05 am | G36: J00WT7100 | I36: 1 | J36: Yes | K36: 72 | L36: PM17 | M36: 1750 | P36: 45750 | R36: 4 | S36: 7000 | T36: PE | U36: 80834730001 | V36: 0 | W36: 5000 | X36: 2000 | Y36: 0 | Z36: 0 | AA36: 0 | AD36: 0 | AM36: 8083473 | AN36: B02083 | AP36: 0 | AQ36: 0 | AR36: 0 | AS36: 0 | AT36: 0 | AU36: 0 | AY36: No | AZ36: W664620 | BA36: 0 | BC36: B02083 | BF36: S0361716
A37: W0682299 | B37: 10000 | C37: 10000 | D37: 45751 | E37: 502LAUGH | F37: 8:32:42 am | G37: L5305U8039 | I37: 1 | J37: Yes | K37: 65 | L37: PMJ7 | M37: 6667 | P37: 45750 | R37: 3 | S37: 20001 | T37: PE | U37: LABEL CLNRM-2X50001 | V37: 0 | W37: 20000 | X37: 1 | Y37: 0 | Z37: 0 | AA37: 0 | AD37: 0 | AM37: LABEL CLNRM-2X5 | AN37: I09146 | AP37: 0 | AQ37: 0 | AR37: 0 | AS37: 0 | AT37: 0 | AU37: 0 | AY37: No | AZ37: W664157 | BA37: 0 | BC37: I09146 | BF37: S0361746
A38: W0682336 | B38: 10000 | C38: 10000 | D38: 45750 | E38: 502LAUGH | F38: 0.42506944 | G38: L5305U8039 | I38: 1 | J38: Yes | K38: 78 | L38: PM84 | M38: 3000 | P38: 45750 | R38: 1 | S38: 3000 | T38: PE | U38: SCREAMER LB-80X10001 | V38: 0 | W38: 3000 | X38: 0 | Y38: 0 | Z38: 0 | AA38: 0 | AD38: 0 | AM38: SCREAMER LB-80X134MM | AN38: I09146 | AP38: 0 | AQ38: 0 | AR38: 0 | AS38: 0 | AT38: 0 | AU38: 0 | AY38: No | AZ38: W664161 | BA38: 0 | BC38: I09146 | BF38: S0361843
A39: W0682348 | B39: 10000 | C39: 10000 | D39: 45751 | E39: 502LAUGH | F39: 8:40:17 am | G39: 4177S1 | I39: 1 | J39: Yes | K39: 61 | L39: PM68 | M39: 1000 | P39: 45750 | R39: 5 | S39: 5000 | T39: PE | U39: 704845 INDEX000001 | V39: 0 | W39: 5000 | X39: 0 | Y39: 0 | Z39: 0 | AA39: 0 | AD39: 0 | AM39: 704845 INDEX00 | AN39: V22000-RO | AP39: 0 | AQ39: 0 | AR39: 0 | AS39: 0 | AT39: 0 | AU39: 0 | AY39: No | AZ39: W664162 | BA39: 0 | BC39: V22000-RO | BF39: S0361761
A40: W0682350 | B40: 10000 | C40: 20000 | D40: 45751 | E40: 502LAUGH | F40: 5:17:08 pm | G40: 10620258022 | I40: 2 | J40: Yes | K40: 77 | L40: PM74 | M40: 130 | P40: 45750 | R40: 154 | S40: 20020 | T40: PE | U40: G0Z24-800110001 | V40: 0 | W40: 5000 | X40: 15020 | Y40: 0 | Z40: 0 | AA40: 0 | AD40: 0 | AM40: G0Z24-80011 | AN40: H08031-JIM | AP40: 0 | AQ40: 0 | AR40: 0 | AS40: 0 | AT40: 0 | AU40: 0 | AY40: No | AZ40: W665431 | BA40: 0 | BC40: H08031-JIM | BF40: S0361847
A41: W0682378 | B41: 10000 | C41: 10000 | D41: 45750 | E41: 502LAUGH | F41: 3:56:06 pm | G41: 4067S1 | I41: 1 | J41: Yes | K41: 22 | L41: PS13 | M41: 5000 | P41: 45750 | R41: 2 | S41: 10000 | T41: PE | U41: 805589 REV4000001 | V41: 0 | W41: 10000 | X41: 0 | Y41: 0 | Z41: 0 | AA41: 0 | AD41: 0 | AM41: 805589 REV400 | AN41: V22000 | AP41: 0 | AQ41: 0 | AR41: 0 | AS41: 0 | AT41: 0 | AU41: 0 | AY41: No | AZ41: W664163 | BA41: 0 | BC41: V22000 | BF41: S0361869
...

Sheet 04-Apr
A1: Production Output
A2: Filter: Date Completed: 04/04/25
A4: Work Order No. | B4: Work Order Line No. | C4: WO Journal Line No. | D4: Add Date | E4: Add User | F4: Add Time | G4: Material Batch No. | H4: Die Cut | I4: Process No. | J4: Posted | K4: Machine Code | L4: Staff Code | M4: No. of Press | N4: Date Started | O4: Time Started | P4: Date Completed | Q4: Time Completed | R4: No. of Ups | S4: Printed Quantity | T4: Journal Type | U4: Item Code | V4: Quantity | W4: QC Approved Quantity | X4: Rejected Quantity | Y4: Roll | Z4: Length | AA4: Width | AB4: Length UOM | AC4: Width UOM | AD4: RM Quantity | AE4: Material Code | AF4: Variant Code | AG4: Request Delivery Date | AH4: Non QC Record | AI4: Link to Line No. | AJ4: Related | AK4: Expire Date | AL4: Label Remark | AM4: Customer Part Number | AN4: Customer Code | AO4: ddmm | AP4: Label Packing Quantity 1 | AQ4: Label Quantity 1 | AR4: Label Packing Quantity 2 | AS4: Label Quantity 2 | AT4: Label Packing Quantity 3 | AU4: Label Quantity 3 | AV4: UOM for Label Printing | AW4: QC Inspector | AX4: Summarised Period | AY4: Summarised | AZ4: Posted Work Order No. | BA4: Colour | BB4: Currency | BC4: Ref Customer | BD4: Group | BE4: PO | BF4: Source Doc. No.
A5: W0680557 | B5: 10000 | C5: 20000 | D5: 45754 | E5: 505KANGHS | F5: 5:38:32 pm | G5: M0BTQ4840 | H5: FSC30666 | I5: 1 | J5: No | K5: 94 | L5: PM09 | M5: 3334 | P5: 45751 | R5: 6 | S5: 20004 | T5: PE | U5: L001-773057-00000004 | V5: 0 | W5: 0 | X5: 0 | Y5: 0 | Z5: 0 | AA5: 0 | AD5: 0 | AH5: No | AI5: 0 | AJ5: No | AM5: L001-773057-000004CM | AN5: W23041-TH | AP5: 0 | AQ5: 0 | AR5: 0 | AS5: 0 | AT5: 0 | AU5: 0 | AY5: No | BC5: W23041-TH | BF5: H0064673
A6: W0682349 | B6: 10000 | C6: 20000 | D6: 45751 | E6: 502LAUGH | F6: 5:16:20 pm | G6: 10620258022 | H6: FDC30934 | I6: 2 | J6: No | K6: 77 | L6: PM74 | M6: 454 | P6: 45751 | R6: 15 | S6: 6810 | T6: PE | U6: CZ633-800050001 | V6: 0 | W6: 0 | X6: 0 | Y6: 0 | Z6: 0 | AA6: 0 | AD6: 0 | AH6: No | AI6: 0 | AJ6: No | AM6: CZ633-80005 | AN6: H08031-JIM | AP6: 0 | AQ6: 0 | AR6: 0 | AS6: 0 | AT6: 0 | AU6: 0 | AY6: No | BC6: H08031-JIM | BF6: S0361845
A7: W0682425 | B7: 10000 | C7: 20000 | D7: 45751 | E7: 502LAUGH | F7: 5:15:26 pm | G7: 10620258022 | H7: FDC30934 | I7: 2 | J7: No | K7: 77 | L7: PM74 | M7: 367 | P7: 45751 | R7: 15 | S7: 5505 | T7: PE | U7: CZ635-800050001 | V7: 0 | W7: 0 | X7: 0 | Y7: 0 | Z7: 0 | AA7: 0 | AD7: 0 | AH7: No | AI7: 0 | AJ7: No | AM7: CZ635-80005 | AN7: H08031-JIM | AP7: 0 | AQ7: 0 | AR7: 0 | AS7: 0 | AT7: 0 | AU7: 0 | AY7: No | BC7: H08031-JIM | BF7: S0361902
A8: W0676952 | B8: 10000 | C8: 30000 | D8: 45754 | E8: 502LAUGH | F8: 8:46:12 am | G8: 10639931106/10639931103/10639931102/10639931104 | I8: 3 | J8: Yes | K8: 91 | L8: QM54 | M8: 56000 | P8: 45751 | R8: 9 | S8: 504000 | T8: PE | U8: 5180-0102-BH2120001 | V8: 0 | W8: 500000 | X8: 4000 | Y8: 0 | Z8: 0 | AA8: 0 | AD8: 0 | AM8: 5180-0102-BH212 | AN8: H08031-JIM | AP8: 0 | AQ8: 0 | AR8: 0 | AS8: 0 | AT8: 0 | AU8: 0 | AY8: No | AZ8: W664482 | BA8: 0 | BC8: H08031-JIM | BF8: S0355320
A9: W0678734 | B9: 10000 | C9: 30000 | D9: 45751 | E9: 502LAUGH | F9: 5:13:10 pm | G9: M0BU23510990/MOBVG3280 | I9: 1 | J9: Yes | K9: 86 | L9: PS96 | M9: 8000 | P9: 45751 | R9: 6 | S9: 48000 | T9: PE | U9: 10036212001 REVA0001 | V9: 0 | W9: 47059 | X9: 941 | Y9: 0 | Z9: 0 | AA9: 0 | AD9: 0 | AM9: 10036212001 REVA | AN9: E05166-JAPAC | AP9: 0 | AQ9: 0 | AR9: 0 | AS9: 0 | AT9: 0 | AU9: 0 | AY9: No | AZ9: W664072 | BA9: 0 | BC9: E05166-JAPAC | BF9: S0357484
A10: W0680983 | B10: 10000 | C10: 10000 | D10: 45758 | E10: 502LAUGH | F10: 9:12:17 am | G10: WO2024/5284/1010831/XHX24911A1407/XHX2412190201/80117500 | I10: 1 | J10: Yes | K10: 103 | L10: PM47 | M10: 90000 | P10: 45751 | R10: 8 | S10: 720000 | T10: PE | U10: MT273730001 | V10: 0 | W10: 720000 | X10: 0 | Y10: 0 | Z10: 0 | AA10: 0 | AD10: 0 | AM10: MT27373 | AN10: Z26002 | AP10: 0 | AQ10: 0 | AR10: 0 | AS10: 0 | AT10: 0 | AU10: 0 | AY10: No | AZ10: W664507 | BA10: 0 | BC10: Z26002 | BF10: S0360896
